Workbook

Sheet 说明
A1: 中国土地契约（匹兹堡大学 Chinese Land Records, 1584–1978）全件辨读统计表
A3: 来源 | B3: Chinese Land Records, 1584-1978, EAL.2011.01, Archives & Special Collections, University of Pittsburgh Library System. https://digital.library.pitt.edu/collection/chinese-land-records
A4: 范围 | B4: 全部 234 件（407 页图像）。每件一行；若一件含多份文书（正契、契尾、验契凭证等），主要字段记主契，其余写在"附带文书"栏。
A5: 方法 | B5: 根据课程资料包中的图像逐页辨读（2026-10-07，由 Claude 分批完成）。人名、地名等文字统一转为简体；看不清的字作 □，存疑的字加 (?)。
A6: 置信度 | B6: 高＝主要字段清楚；中＝部分存疑；低＝大部分难辨或残缺（共 12 件，在总表中以红色标出，「中」为黄色）。
A7: 派生字段 | B7: "文书大类""交易物大类""时期""币种"是在原判基础上归并的分类，便于统计；原判保留在"文书类型（原判）""交易物类别（原判）"栏。
A8: 县 | B8: 按契文辨读，不照搬目录。闽县、侯官县（清代）与闽侯县（1913 年后）、林森县（1944–1949）在地理上大体重叠，统计时未合并。无法判断者记"不详"。
A9: 价格 | B9: "价格数值"只记契面数字，不做币值换算；银两、银元、铜钱、法币、人民币各自独立。找贴、凑断契的价格是加价部分。官方凭证的税额、纸价记在"价格原文"，不计入价格统计。
A10: 与目录不符 | B10: 图书馆目录（"图书馆目录标题""目录日期"）与图像不一致之处记在"与目录不符"栏，常见情况是把典契记成买卖、买卖方向写反、把中人或保人当成买主、年份换算差一年。
A11: 使用限制 | B11: 图像仅限课堂使用，本表不含任何图像；查看原件请点"链接"栏，引用时请注明匹兹堡大学图书馆。辨读结果未经人工校对，正式引用前请核对原图。
A13: 工作表 | B13: 总表：全部 234 件明细，可筛选；统计：按类别、时期、性别、县等计数，以及按币种 × 时期的价格表（公式随总表更新）；人物索引：重复出现的中人、代笔。

Sheet 总表
A1: 箱 | B1: 夹 | C1: 文书大类 | D1: 文书类型（原判） | E1: 时期 | F1: 年号 | G1: 纪年原文 | H1: 公元年 | I1: 立契人 | J1: 立契人性别 | K1: 立契人身份 | L1: 承受人 | M1: 县 | N1: 地点原文 | O1: 交易物大类 | P1: 交易物类别（原判） | Q1: 交易物细节 | R1: 价格原文 | S1: 价格数值 | T1: 币种 | U1: 中人 | V1: 在见／知见／保人 | W1: 代笔 | X1: 官印／税契 | Y1: 回赎／期限条款 | Z1: 附带文书 | AA1: 值得注意 | AB1: 与目录不符 | AC1: 置信度 | AD1: 存疑 | AE1: 页数 | AF1: 图书馆目录标题 | AG1: 目录日期 | AH1: 链接 | AI1: item_id
A2: 1 | B2: 1 | C2: 其他 | D2: 其他（清丈归户单） | E2: 1 明（-1643） | F2: 万历 | G2: 万历十二年十二月 日 | H2: 1584 | I2: 张炳财 | J2: 男 | K2: 表席里叁图贰甲户长；户丁张万殿执业；纳粮佃户'自'，系民田 | M2: 连城县 | N2: 连城县□□表席里叁图，大土名莲花坑，小土名赤岭 | O2: 田 | P2: 田 | Q2: 吕字壹千伍百柒拾捌号田壹坵；四至：东至一千五百七十二号吴世源界，西至一千五百七十四号吴大传界，南至一千六百五十七号吴光裕界，北至一千五百六十八号张族(?)负(?)界；东丈中直贰拾叁号壹尺、西丈一广叁号、南丈二广陆号伍尺、北丈三广捌号；通计壹百肆拾陆(?)步□分，折田□亩肆分陆厘贰毫(?) | V2: 公正余(?)易(?)美；书算吴□祥 | X2: 木刻印刷格式官方单据，未见红印；照上田起科 | AA2: 万历清丈（张居正丈田）后颁发的归户单，印刷版式填写，以千字文'吕'字编号鱼鳞图册号；是本特藏最早一件，且出自闽西连城而非福州。左边沿有一行模糊墨书批注。 | AC2: 中 | AD2: 旧额亩分、今丈数字及通计步数字迹模糊；公正、书算姓名不确定；北至人名'张族负'存疑 | AE2: 1 | AF2: Owner: 張炳財 [ZHANG Bingcai] -- Place: 福建省連城縣 [Fujian Sheng Liancheng Xian] -- Personal | AG2: 1584 | AH2: 查看原件 | AI2: 31735066267786
A3: 1 | B3: 2 | C3: 买卖（卖／卖断） | D3: 卖契 | E3: 2 清前期（1644-1795） | F3: 顺治 | G3: 顺治十六年□月 日 | H3: 1659 | I3: 范南山 | J3: 男 | K3: 承祖遗下荒山 | L3: 刘宅 | M3: 不详 | N3: 坐落铁狮峯下□□塝□内（土名不全） | O3: 坟地 | P3: 坟地＋山／山林 | Q3: 祖遗荒山一片内抽出一穴，卖与刘宅边前去安葬坟墓 | R3: 时值价银伍钱正 | S3: 0.5 | T3: 银两 | U3: 魏玉璟(?)（说谕人） | V3: 萧秀(?)卿（在见人） | W3: 揭时发(?)（代字人） | X3: 无官印（白契） | Y3: 卖出一穴听买主择日安葬；如有来历不明、出头抵当，不涉买主之事 | AA3: 只卖荒山中一个坟穴，价仅五钱；契纸左方背面大字墨书'福地'。用'说谕人'称中人。 | AC3: 中 | AD3: 月份字不清；土名、中人及代字人名字有存疑 | AE3: 1 | AF3: Seller: 范南山 [FAN Nanshan] -- Personal | AG3: 1659 | AH3: 查看原件 | AI3: 31735066267711
A4: 1 | B4: 3 | C4: 买卖（卖／卖断） | D4: 卖契 | E4: 2 清前期（1644-1795） | F4: 康熙 | G4: 康熙十七年三月十九日 | H4: 1678 | I4: 徐正耀 | J4: 男 | K4: 原祖置为正屋；声明与徐家伯叔兄弟子孙无干 | L4: 杨元管(?)（杨家） | M4: 闽清县 | N4: 闽清县十都□墘地方，土名井墘厝 | O4: 屋／厝 | P4: 屋＋山／山林 | Q4: 正屋壹座六扇五间，上至椽尾下至地基，内有书院壹间空地；连屋后竹林、山业、竹树、水尾牛栏(?)等，统卖与杨家永远起盖住居；四至含水圳、后门阳塝等 | R4: 价银拾捌两正，其银水九五色 | S4: 18 | T4: 银两 | U4: 吴朝宇(?) | W4: 陈五(?)费(?) | X4: 钤闽清县官印多方（红契），左下另有骑缝半印 | Y4: 统卖与杨家永远起盖住居；日后不得言找言赎，如有来历不明，徐家出头支当 | AA4: 清初闽清县红契，盖有大方县印；房屋与竹林山场连带出售。契末有'劈'字骑缝半字。 | AB4: 目录地点作 unknown，契文明载闽清县十都 | AC4: 中 | AD4: 买主名'杨元管'、地名'□墘'、代字人名字存疑；银色'九五'存疑 | AE4: 1 | AF4: Seller: 徐正耀 [XU Zhengyao] -- Place: unknown -- Government | AG4: 1678 | AH4: 查看原件 | AI4: 31735066267729
A5: 1 | B5: 4 | C5: 典当／胎借 | D5: 典契 | E5: 2 清前期（1644-1795） | F5: 乾隆 | G5: 乾隆贰拾伍年伍月 日 | H5: 1760 | I5: 黄毓扆 | J5: 男 | K5: 承祖有民田；凑字中称受主为表伯 | L5: 未写名（凑字称'业表伯处'） | M5: 闽清县 | N5: 拾壹都地方，土名和尚墘、长垅、平水潭台尾、上下大坵尾园前后埕利、吴厝洋上中段、桑园二小坵等处 | O5: 田 | P5: 田 | Q5: 民田数号：佃陈朝彩，土名和尚墘，载租米壹石捌斗；佃许继实，土名长垅平水潭台尾，抽出租米壹石壹(?)斗伍升；佃林于(?)奏(?)，土名上下大坵尾园前后埕利吴厝洋上中段、桑园二小坵，载租米贰石柒斗 | R5: 价银陆拾叁两正，纹广(?)；凑字另凑钱壹拾千文(?) | S5: 63 | T5: 银两 | U5: 薛宜(?)章 | V5: 刘有堂（在见）；谢朝尊(?)；刘有炳(?)（凑字中见） | X5: 两纸均钤方形红官印（县印，印文不清），属红契 | Y5: 典契：限伍年满之日备银取赎；凑字后仍限期取赎 | Z5: 1) 典契，乾隆贰拾伍年伍月，黄毓扆将民田数号（载租米合伍硕余）典出，价银陆拾叁两，限伍年备银取赎；2) 凑字（找贴契），乾隆叁拾贰年伍月，黄毓扆就前典田再向业主表伯处凑出钱壹拾千文(?)，亦钤红印 | AA5: 典与找凑相隔七年，典价外再凑钱，体现'典—凑'的逐步出让；典契附'计开'逐佃列租。契纸左侧有椭圆墨圈内书'大吉(?)'字样。 | AB5: 契文未写县名，目录作闽清县；目录以黄毓扆为Owner | AC5: 中 | AD5: 受主姓名未见；凑字钱数及中见名字草书存疑；部分租额数字存疑 | AE5: 2 | AF5: Owner: 黃毓扆 [HUANG Yuyi] -- Place: 福建省閩清縣 [Fujian Sheng Minqing Xian] -- Government | AG5: 1760 to 1767 | AH5: 查看原件 | AI5: 31735064607546
A6: 1 | B6: 5 | C6: 买卖（卖／卖断） | D6: 卖契 | E6: 2 清前期（1644-1795） | F6: 乾隆 | G6: 乾隆贰拾陆年辛巳岁拾月初二日 | H6: 1761 | I6: 许琼栢、许奕栢 | J6: 男 | K6: 许氏贰房叔侄，祖父遗下山埔 | L6: 吴省忠叔侄 | M6: 永定县 | N6: 土名大溪边磜下尚上 | O6: 山林 | P6: 山／山林＋坟地 | Q6: 山埔壹所，原有土窨贰穴；上至许家坟下为界，下至圳面为界，左右并无土窨相连；准吴家坟安葬 | R6: 九四(?)足色价银叁拾两正 | S6: 30 | T6: 银两 | U6: 官盛清（说合人） | V6: 许芳栢（房户/房亲）；全侄许恭上、许信上等（同立） | X6: 契面钤永定县印多方（红契）；附乾隆二十七年契尾，纳税银玖钱（税率3%） | Y6: 永远为照；不得重复典当、言阻 | Z6: 1) 卖山埔土窨契，乾隆贰拾陆年辛巳拾月初二日，许琼栢、许奕栢卖与吴省忠叔侄，价银叁拾两，钤永定县印；2) 契尾，乾隆贰拾柒年捌月，永字一千四百十三号，业户吴省忠买许琼栢、许奕栢坐落大溪边磜下尚上土窨，用价银叁拾两，纳税银玖钱正，钤永定县印 | AA6: 契尾印刷文引乾隆十五年布政使司奏准契尾格式，前后幅分写；税额正好为价银百分之三。卖的是坟穴用的'土窨'。 | AB6: 目录年代1761-1762与正契、契尾吻合 | AC6: 中 | AD6: 银色成数及同立侄名字存疑 | AE6: 2 | AF6: Seller: 許瓊栢 [XU Qiongbai] -- Buyer: 吳省忠 [WU Shengzhong] -- Place: 福建省永定縣 [Fujian Sheng Yongding Xian] -- Government | AG6: 1761 to 1762 | AH6: 查看原件 | AI6: 31735064607538
A7: 1 | B7: 6 | C7: 买卖（卖／卖断） | D7: 卖契 | E7: 2 清前期（1644-1795） | F7: 乾隆 | G7: 乾隆叁拾贰年拾贰月 日 | H7: 1767 | I7: 徐干通（仝侄徐士孚） | J7: 男 | K7: 叔侄同立；承祖遗下苗田 | L7: 峡阳应熊孙 | M7: 南平县 | N7: 坐落土名小溪漈下垅（峡阳） | O7: 田 | P7: 田 | Q7: 苗田一段，年收苗谷柒箩伍斗，实载苗米柒升伍合(?)；先年已抽出苗谷□箩捌斗与应熊孙为业，此次再卖自己名下苗谷陆斗贰升伍合，实载民苗陆合贰(?)；另随田鸭肆只；粮米在梅北二图三甲徐壬童户内推出，收入峡阳二图二甲应熊茂户内完粮 | R7: 时值土风实卖得契价纹银贰两贰钱正 | S7: 2.2 | T7: 银两 | U7: 徐起孙（代字中） | W7: 徐起孙（代字中） | X7: 钤红色斜方官印数方（红契），印文不清 | Y7: 卖契；声明未曾典挂外人财物，无准折之类，二家各无悔 | AA7: 契内先问房亲兄弟不愿承买，方卖与峡阳应家；'随田鸭'作为附随物一并出卖，罕见。粮户推收写明图甲户名。 | AB7: 目录买主作'熊孙?'，契文为'应熊孙'；目录作南平县，契文只见峡阳、梅北等地名（峡阳属南平） | AC7: 中 | AD7: 契纸有两处虫蛀洞，'先年'抽出谷数、苗米合数不全；代字中名字'起孙'存疑 | AE7: 1 | AF7: Seller: 徐幹通 [XU Gantong] -- Buyer: 熊孫? [XIONG Sun?] -- Place: 福建省南平縣 [Fujian Sheng Nanping Xian] -- Government | AG7: 1767 | AH7: 查看原件 | AI7: 31735066237367
A8: 1 | B8: 7 | C8: 找贴／凑断 | D8: 找贴契／贴尽契 | E8: 2 清前期（1644-1795） | F8: 乾隆 | G8: 乾隆四十四年拾月 日 | H8: 1779 | I8: 李有定 | J8: 男 | K8: 其祖母于乾隆叁拾壹(?)年间手将民田典在谢处，今再立凑字 | L8: 谢（谢家） | M8: 闽清县 | N8: 闽清县陈洋地方 | O8: 田 | P8: 田 | Q8: 民田数号，租额土名俱载在原契内 | R8: 凑出价银贰两五钱正 | S8: 2.5 | T8: 银两 | V8: 段章绶（在见） | X8: 钤大方红官印（斜盖），属红契 | Y8: 面约加限叁年，限满之日听李家备价照原凑契面银两赎回，谢家不得执留 | AA8: 典后加凑并延长赎回期限三年，是典—凑关系的典型样本；出典人为祖母，由孙辈立凑字。 | AB8: 目录买主作'谢氏'，契文作'谢'（谢家），未见'氏'字 | AC8: 高 | AD8: 原典年份'乾隆叁拾壹年'中'壹'字存疑 | AE8: 1 | AF8: Seller: 李有定 [LI Youding] -- Buyer: 謝氏 [XIE] -- Place: 福建省閩清縣 [Fujian Sheng Minqing Xian] -- Government | AG8: 1779 | AH8: 查看原件 | AI8: 31735066237375
A9: 1 | B9: 8 | C9: 买卖（卖／卖断） | D9: 卖契 | E9: 2 清前期（1644-1795） | F9: 乾隆 | G9: 乾隆肆拾玖年拾贰月 日 | H9: 1784 | I9: 熊长生（同侄熊亨伦、熊亨乡） | J9: 男 | K9: 叔侄同立；田系自己所置 | L9: 熊亨读（本房堂侄） | M9: 古田县 | N9: 本处土名俗呌门首亭下大垅 | O9: 田 | P9: 田 | Q9: 民田壹号，受种壹拾伍石，该粮壹亩壹分贰厘伍毫；田叁年以后肆年当收 | R9: 时值价银壹拾玖两广正，每两的钱捌百文正 | S9: 19 | T9: 银两 | U9: 郑成富 | V9: 熊元廷（在见人） | W9: 张东礼(?)（代笔人） | X9: 卖契钤斜方红印一方；附古田县契尾（布政使司印、县印多方），纳税银壹两伍钱（价银3%） | Y9: 面约五拾叁年(?)备价赎田，不得刁难；若无力之日推入读户，买主管耕 | Z9: 1) 卖契，乾隆肆拾玖年拾贰月，熊长生同侄亨伦、亨乡将民田一号卖与本房堂侄熊亨读，价银壹拾玖两（每两折钱捌百文）；2) 契尾，道光拾□年（?），布字贰千玖百贰拾贰号，古田县业户黄鸿吉于道光二年买□廷乐(?)辛(?)氏田叁亩，坐落十八都土名报慈(?)，用价银伍拾两，纳税银壹两伍钱 | AA9: 族内买卖（叔卖与堂侄），价以银两计而折钱交付；所附契尾是道光年间黄鸿吉另一宗买田的税凭，与正契交易人不同，可能是同一田块后来转手到黄家（目录将黄鸿吉列为Owner）。契末大字'斋否(?)'。 | AB9: 目录年代1784–1830；契尾年份为道光拾□年，可能晚于1830 | AC9: 中 | AD9: 契尾年份、卖主姓名'廷乐辛氏'存疑；赎期'五拾叁年'理解存疑；代笔人名字末字不清 | AE9: 2 | AF9: Owner: 黃鴻吉 [HUANG Hongji] --Seller: 熊長生 [XIONG Changsheng] -- Buyer: 熊亨讀 [XIONG Hengdu] -- Place: 福建省古田縣 [Fujian Sheng Gutian Xian] -- Government | AG9: 1784 to 1830 | AH9: 查看原件 | AI9: 31735066237334
A10: 1 | B10: 9 | C10: 找贴／凑断 | D10: 找贴契／贴尽契 | E10: 2 清前期（1644-1795） | F10: 乾隆 | G10: 乾隆肆拾柒年玖月 日 | H10: 1782 | I10: 应梓龙 | J10: 男 | K10: 本年先已卖断，今再增找杜断 | L10: 刘继伍 | M10: 建阳县 | N10: 坐落磋上横窠(?)游岭黄厝垅 | O10: 田 | P10: 田 | Q10: 田皮骨（连皮带骨）米柒箩伍管正 | R10: 增找得杜断价纹银壹拾柒两正；外用中见礼银伍钱壹分正 | S10: 17 | T10: 银两 | U10: 刘礼□（原中人）；刘兆华（劝谕人） | V10: 应梓明（知契人） | W10: 徐(?)迟(?)万(?)（代字人） | X10: 钤建阳县印多方（红契） | Y10: 增找杜断之后仍凭买主永远管业，交租割过户当差完粮；永无言增言找之理 | AA10: 同年先卖断后再增找，'田皮骨'一并出卖；另记中见礼银，显示中人报酬。 | AC10: 中 | AD10: 地名'磋上横窠'、原中人名、代字人名字存疑 | AE10: 1 | AF10: Seller: 應梓龍 [YING Zilong] -- Buyer: 劉繼伍 [LIU Jiwu] -- Place: 福建省建陽縣 [Fujian Sheng Jianyang Xian] -- Government | AG10: 1782 | AH10: 查看原件 | AI10: 31735064607678
A11: 1 | B11: 10 | C11: 典当／胎借 | D11: 典契 | E11: 2 清前期（1644-1795） | F11: 乾隆 | G11: 乾隆四十七年十二月(?) 日 | H11: 1782 | I11: 可翅（叔） | J11: 男 | K11: 承祖手置得潘亨选根面全民田；母陈(?)氏知契 | L11: 侄钦家(?)（钦□） | M11: 不详 | N11: 廿五都土名廖四田地方 | O11: 田 | P11: 田 | Q11: 根面全民田壹号，丈计玖分，粮札载在海字壹千九百壹拾叁号 | R11: 典出价银拾两正纹广 | S11: 10 | T11: 银两 | U11: 程叔顺（中人） | V11: 陈(?)氏（知契母）；兄可森（在见）；叔志涵（仝见） | W11: 自笔 | X11: 无官印（白契） | Y11: 粮色两约六年为限，限满之日听叔照契银两依期取赎，不得执留 | AA11: 叔将田'缴典'与侄；粮立在廿五都四甲林光鹏户下，听侄过甲入户。契纸左上有大字'大吉'。 | AB11: 目录卖主作'可翅'，契中自称'叔可翅'，未写姓 | AC11: 中 | AD11: 月份、受典侄名字、知契母姓氏为草书，存疑 | AE11: 1 | AF11: Seller: 可翅 [KE Chi] -- Place: unknown --Personal | AG11: 1782 | AH11: 查看原件 | AI11: 31735066267844
A12: 1 | B12: 11 | C12: 找贴／凑断 | D12: 找贴契／贴尽契 | E12: 3 嘉道（1796-1850） | F12: 嘉庆 | G12: 嘉庆叁年贰月 日 | H12: 1798 | I12: 刘盛章 | J12: 男 | K12: 旧年冬已将房屋卖断与本族，今再增找杜断 | L12: 刘咸安、刘道建（本族） | M12: 建阳县 | N12: 坐落水北(?) | O12: 屋／厝 | P12: 屋＋地基／屋地 | Q12: 朽房屋地基共计叁榈，四至银两前契载明 | R12: 增找杜断价纹银捌两正；外用中银贰钱肆分正 | S12: 8 | T12: 银两 | U12: 刘如万（原中代字人） | W12: 刘如万（原中代字人） | X12: 钤建阳县印多方（红契） | Y12: 增找杜断之后，仍凭买者永远管业修整架造，开门出入，卖者不敢阻占；日后不得另生枝节言增言找 | AA12: 与 Folder 13（刘咸安契尾，嘉庆十年）为同一宗族内房屋交易的连续文书。 | AC12: 高 | AD12: 地名'水北'存疑 | AE12: 1 | AF12: Seller: 劉盛章 [LIU Shengzhang] --Buyer: 劉咸安 [LIU Xian'an] and 劉道建 [LIU Daojian] -- Place: 福建省建陽縣 [Fujian Sheng Jianyang Xian] -- Government | AG12: 1798 | AH12: 查看原件 | AI12: 31735064607652
A13: 1 | B13: 12 | C13: 找贴／凑断 | D13: 找贴契／贴尽契 | E13: 3 嘉道（1796-1850） | F13: 嘉庆 | G13: 嘉庆柒年贰月 日 | H13: 1802 | I13: 邱有本（仝弟邱有炳、侄邱传学） | J13: 男 | K13: 承嗣祖手置民田；乾隆年间经嗣祖妣手典与傅处；今因造垄（营葬）嗣祖妣急用 | L13: 傅（傅处） | M13: 闽清县 | N13: 闽清十七都半岭桥头里炉地方，土名南仓下洋下分对面山等处 | O13: 田 | P13: 田 | Q13: 民田数号，租额银两钱文俱载典、凑、尽各契内 | R13: 尽出价银贰拾贰两正纹广 | S13: 22 | T13: 银两 | U13: 弟有汉（中见） | X13: 无官印（白契） | Y13: 立尽契后仍面约年限伍年，限满之日听邱备价照各契面取赎，傅不得执留 | AA13: 名为'尽契'却仍保留伍年后回赎的权利，说明'尽'并不必然等于绝卖；用途写明为给嗣祖妣造坟。 | AC13: 高 | AE13: 1 | AF13: Seller: 邱有本 [QIU Youben] 邱有炳 [QIU Youbing] and 邱傳學 [QIU Chuanxue] -- Place: 福建省閩清縣 [Fujian Sheng Minqing Xian] -- Personal | AG13: 1802 | AH13: 查看原件 | AI13: 31735066266523
A14: 1 | B14: 13 | C14: 契尾／验契 | D14: 契尾 | E14: 3 嘉道（1796-1850） | F14: 嘉庆 | G14: 嘉庆十年五月 日 | H14: 1805 | I14: 刘盛章 | J14: 男 | K14: 契尾所记卖主 | L14: 刘咸安 | M14: 建阳县 | N14: 建阳县 | O14: 屋／厝 | P14: 屋 | Q14: 契尾计开：业户刘咸安买刘盛章厝(?)壹契 | R14: 用价银贰拾柒两(?)；纳税银□钱□分 | S14: 27 | T14: 银两 | X14: 建阳县印多方，契尾编号'徵(?)字□百九十二号'(?) | AA14: 与 Folder 11 刘盛章卖房屋给刘咸安、刘道建的增找契相对应，是同一宗交易后补税的官方凭证。 | AC14: 中 | AD14: 价银、税银数字草书存疑；编号不清 | AE14: 1 | AF14: Owner: 劉咸安 [LIU Xian'an] -- Place: 福建省建陽縣 [Fujian Sheng Jianyang Xian] -- Government | AG14: 1805 | AH14: 查看原件 | AI14: 31735064607660
A15: 1 | B15: 14 | C15: 典当／胎借 | D15: 典契 | E15: 3 嘉道（1796-1850） | F15: 嘉庆 | G15: 嘉庆拾年伍月 日 | H15: 1805 | I15: 赵守藻 | J15: 男 | K15: 嘉庆拾年肆月间买得陶天翰民田面数号，旋即转典 | L15: 林（林处） | M15: 侯官县 | N15: 侯官县草市都 | O15: 田面 | P15: 田面 | Q15: 民田面数号，佃林有栋耕作，递年载早晚租谷壹百柒拾筋；粮挂在草市都五甲陶孔镳户下应粮陆分伍厘；计开：第六区地字五百八十六号土名培下则园丈捌厘、五百八十七号土名坑下则园肆分零叁毫柒丝伍忽、五百八十八号土名荒地下则地贰分贰厘叁毫(?)五忽、五百八十九号土名坑里下则园丈伍厘 | R15: 得讫价银壹拾肆两(?)正 | S15: 14 | T15: 银两 | U15: 杨海武（中见友） | W15: 林标人（代笔） | X15: 钤红官印两方；另有民国时期'西湖区验税契事务所 验讫'朱戳及'验'字小戳 | Y15: 面约叁年为限，限满之日听藻备价照契面银两取赎；并缴陶君良原契壹纸 | AA15: 买入一月后即转典；契面有民国验契机关'西湖区验税契事务所'戳记，显示此契在民国时期仍被拿去验税。与 Folder 19 林有柱契尾相关联。 | AB15: 目录作'卖'，契文实为转典契 | AC15: 中 | AD15: 价银数字、个别田号亩分字存疑 | AE15: 1 | AF15: Seller: 趙守藻 [ZHAO Shouzao] -- Buyer: 林 [LIN] -- Place: 福建省侯官縣 [Fujian Sheng Houguan Xian] -- Government | AG15: 1805 | AH15: 查看原件 | AI15: 31735064607843
A16: 1 | B16: 15 | C16: 租佃／欠租 | D16: 领票／欠租字 | E16: 3 嘉道（1796-1850） | F16: 嘉庆 | G16: 嘉庆拾年至拾叁年 | H16: 1805 | I16: 黄隆贯 | J16: 男 | K16: 收租人（业主）出具收条 | L16: 陈国远代陈国龙；仁标代执惠 | M16: 不详 | O16: 田 | P16: 田 | Q16: 租米：国龙户肆斗肆升；执惠户壹斗陆升（法斗） | R16: 租米肆斗肆升；壹斗陆升 | T16: 米谷 | W16: 黄隆贯（自字） | X16: 无官印；部分收条钤收租人私章 | Z16: 共三页租米收条：1) 嘉庆拾贰年八月廿六日，入仁标租米，黄隆贯字（钤小方印）；2) 同纸两条：嘉庆拾年十二月十七日入陈国远代国龙租米肆斗肆升正，嘉庆拾年十二月十五日入仁标代执惠租米壹斗六升正，均黄隆贯字；3) 同纸两条：嘉庆拾叁年十二月十五日入陈国远代国龙(?)租米肆斗肆升正，嘉庆拾叁年十二月十五日入仁标代执惠租米壹斗陆升正，均黄隆贯字并钤印 | AA16: 每年租额固定，连续数年收条可看出定额租；陈国远为其兄弟代缴。与 Folder 21–23 陈国远、黄隆贯文书相关联。 | AC16: 中 | AD16: 第一条租米数额在纸边缺损处；'仁标''执惠'人名存疑 | AE16: 3 | AF16: Seller: 黃隆貫 [HUANG Longguan] -- Buyer: 陳國遠代陳國龍 [CHEN Huoyuan represents CHEN Guolong] -- Personal | AG16: 1805 to 1808 | AH16: 查看原件 | AI16: 31735066266705
A17: 1 | B17: 16 | C17: 典当／胎借 | D17: 典契 | E17: 3 嘉道（1796-1850） | F17: 嘉庆 | G17: 嘉庆十年六月吉日 | H17: 1805 | I17: 吴秉鉴 | J17: 男 | K17: 王氏知契（当为其母）；胞弟秉钧同押 | L17: 谢先经（据契尾） | M17: 闽县 | N17: 闽县 | O17: 屋／厝 | P17: 屋 | Q17: 据契尾为房屋；正契正文缺 | R17: 契尾：用价银肆拾两正，纳税银壹两贰钱正 | S17: 40 | T17: 银两 | U17: 郑长梅；金存国；郑提登 | V17: 王氏（知契）；胞弟吴秉钧；涂正□（乡保） | W17: 林学纶(?)（秉笔） | X17: 转典契钤闽县印及乡保长方戳；附嘉庆二十一年契尾，钤闽县印多方 | Y17: 转典（条款部分缺失） | Z17: 1) 转典契（残），嘉庆十年六月吉日，吴秉鉴立，正文部分未见，仅存落款；2) 契尾，嘉庆贰拾壹年肆月，闽县业户谢先经买吴秉鉴屋，用价银肆拾两，纳税银壹两贰钱 | AA17: 转典契后十一年才由谢先经买绝并纳税；契上有'乡保'署名及戳记。契纸左侧大字'大吉昌(?)'。 | AC17: 中 | AD17: 正契正文缺损未见；秉笔人、乡保名字存疑；契尾编号不清 | AE17: 2 | AF17: Owner: 吳秉鑒 [WU Bingjian] -- Seller: 吳秉鑒 [WU Bingjian] -- Buyer: 謝先經 [XIE Xianjing] -- Place: 福建省閩縣 [Fujian Sheng Min Xian] -- Government | AG17: 1805 to 1816 | AH17: 查看原件 | AI17: 31735064607579
A18: 1 | B18: 17 | C18: 契尾／验契 | D18: 契尾 | E18: 3 嘉道（1796-1850） | F18: 嘉庆 | G18: 嘉庆拾贰年拾(?)月 日 | H18: 1807 | J18: 不详 | L18: 罗□ | M18: 歙县 | N18: 歙县 | O18: 田 | P18: 田 | Q18: 契尾计开：买田(?)□号 | R18: 用价银壹拾伍两，纳税银肆钱伍分(?) | S18: 15 | T18: 银两 | X18: 江南安徽等处承宣布政使司契尾，钤布政使司及县印 | AA18: 批次中唯一一件安徽（徽州歙县）文书，契尾格式与福建契尾不同（顶部有'契尾'大字及宝珠纹）。 | AB18: 目录日期空缺，契尾写嘉庆拾贰年（1807） | AC18: 低 | AD18: 业户名仅见'罗'字；编号、卖主、税额不清；纸张破损 | AE18: 1 | AF18: Owner: 羅? [LUO ?] -- Place: 安徽省歙縣 [Anhui Sheng She Xian] -- Government | AH18: 查看原件 | AI18: 31735066237409
A19: 1 | B19: 18 | C19: 契尾／验契 | D19: 契尾 | E19: 3 嘉道（1796-1850） | F19: 嘉庆 | G19: 嘉庆十八年八月 日 | H19: 1813 | I19: 刘钦达 | J19: 男 | K19: 契尾所记卖主 | L19: 刘王建 | M19: 建阳县 | N19: 建阳县 | O19: 田 | P19: 田 | Q19: 契尾计开：业户刘王建买刘钦达田，坐落□□（未填全） | R19: 用价银贰拾伍(?)两；纳税银壹两□□(?) | S19: 25 | T19: 银两 | X19: 福建布政使司契尾，布字壹拾贰万玖千玖百叁拾玖号，钤建阳县印多方；契尾顶端骑缝号'□字□柳(?)廿九号' | AA19: 布字编号已达十二万余号，可见嘉庆后期契尾发行量。刘王建与 Folder 11、13 的刘咸安、刘道建、刘盛章同属建阳刘氏，可能同一宗族。 | AB19: 目录卖主作'刘钦达(违)'，契尾写'刘钦达'，'违'字未见 | AC19: 中 | AD19: 价银数字与税银数字草书存疑（若价银25两，3%税应为柒钱伍分，与所见'壹两'不符） | AE19: 1 | AF19: Seller: 劉欽達(違) [LIU Qinda(wei)] -- Buyer: 劉王建 [LIU Wangjian] -- Place: 福建省建陽縣 [Fujian Sheng Jianyang Xian] --Government | AG19: 1813 | AH19: 查看原件 | AI19: 31735066267471
A20: 1 | B20: 19 | C20: 契尾／验契 | D20: 契尾 | E20: 3 嘉道（1796-1850） | F20: 嘉庆 | G20: 嘉庆贰拾贰年贰月 日 | H20: 1817 | I20: 赵守藻 | J20: 男 | K20: 契尾所记卖主 | L20: 林有柱 | M20: 侯官县 | N20: 侯官县 | O20: 田 | P20: 田 | Q20: 契尾计开：业户林有柱买赵守藻田壹契，坐落□□ | R20: 用价银□拾柒(?)两；纳税银□两□钱□分 | T20: 银两 | X20: 福建布政使司契尾，布字贰万捌千捌拾叁号，钤侯官县印及布政使司印多方 | AA20: 与 Folder 14 赵守藻1805年转典给'林处'的田契对应：十二年后林有柱买断并纳税，佃户林有栋与买主林有柱可能同族。右上角墨书'久树(?)'。 | AC20: 中 | AD20: 价银、税银数字在印下，难以辨认 | AE20: 1 | AF20: Seller: 趙守藻 [ZHAO Shouzao] -- Buyer: 林有柱 [LIN Youzhu] -- Place: 福建省侯官縣 [Fujian Sheng Houguan Xian] -- Government | AG20: 1817 | AH20: 查看原件 | AI20: 31735064607850
A21: 1 | B21: 20 | C21: 典当／胎借 | D21: 典契 | E21: 3 嘉道（1796-1850） | F21: 道光 | G21: 道光贰年闰叁月吉日 | H21: 1822 | I21: 王志拔 | J21: 男 | K21: 原父手置阄分；父在日重新起盖店屋；今因要用 | L21: 陈（陈处） | M21: 闽县 | N21: 坐产闽(?)邑嘉崇里八(?)甸一中肆保铺沙堤街地方 | O21: 店屋 | P21: 店屋＋地基／屋地 | Q21: 前后两座店屋：原父于乾隆□拾年间用价银壹拾叁两买断陈林氏屋地一所，起盖肆柱店面一榈；嘉庆壹拾年间又用价银壹百贰拾两典得店后史尚才伍柱厝屋一进、二柱厨房一榈；嘉庆拾□年两座俱被火回禄，父在日鸠料将两主空地统重新起盖前伍柱店面一座、中拔榭贰榈又叁柱楼一榈、后拔榭伍榈，外空地一所，园篱一耳至江；道光元年拾贰月史尚才又向拔凑断出屋价银贰拾贰两；四至：前至官街，后至江，左至陈家屋，右至陈家屋，上至椽瓦，下至砾石地基 | R21: 得讫屋价银叁百两正纹广，外加修理银壹拾两，共成银叁百壹拾两 | S21: 310 | T21: 银两 | U21: 陈务睦(?)（中友）；叶闻蔚(?) | V21: 陈国梁(?)（在见） | W21: 王兴朝（代笔） | X21: 无县印；有'地保'长方朱戳（二四保铺保应陞(?)） | Y21: 约年限满之日听拔备价照契面并修理银两赎回，陈家不得执留；面约赎屋之日每两折钱壹千文，用下杭街钱店钱票 | AA21: 随契统付上手契共十五纸（高林周、陈林氏、曾居盛、林文发、郑东人、史尚才等典断契），完整记录一座城区店屋数十年间的买、典、火灾重建、凑断经过；约定赎回时用下杭街钱店钱票。地保戳记显示城市铺保制度。 | AB21: 目录作'王志拨?'与卖契，契文为'王志拔'，且实为典契 | AC21: 中 | AD21: 里甸名、中友及在见人名字存疑；典期年限字迹模糊 | AE21: 1 | AF21: Seller: 王志撥？ [WANG Zhibo] -- Buyer: 陳 [CHEN] -- Personal | AH21: 查看原件 | AI21: 31735066267687
A22: 1 | B22: 21 | C22: 租佃／欠租 | D22: 领票／欠租字 | E22: 3 嘉道（1796-1850） | F22: 道光 | G22: 道光玖年二月 日 | H22: 1829 | I22: 陈国远 | J22: 男 | K22: 欠租佃户，立票人 | L22: 未写名（收租业主，应即黄隆贯） | M22: 不详 | O22: 田 | P22: 田 | Q22: 旧欠租米分期偿还 | R22: 旧欠租米壹石壹斗＋壹石零玖升 | T22: 米谷 | V22: 叶宜全（保票人） | W22: 吴青山（代字） | X22: 无官印 | Y22: 过期每斗每月加利米叁合，系保票代赔无词 | Z22: 同纸两张欠租票：1) 凭票支旧欠租米壹石壹斗正，期至辛卯年八月初十日送仓交纳；2) 凭票支旧欠租米壹石零玖升正，期至辛卯年十二月二十日送仓交纳；两票均道光玖年二月立 | AA22: 欠租转为带利息的期票，保人负代赔责任；立票人名字被墨圈圈出（可能表示已清偿注销）。 | AB22: 目录把叶宜全列作 Buyer，实为保票人 | AC22: 高 | AE22: 1 | AF22: Seller: 陳國遠（立票人） [CHENG Guoyuan] -- Buyer: 葉宜全（保票人） [YE Yiquan] -- Personal | AG22: 1829 | AH22: 查看原件 | AI22: 31735066266580
A23: 1 | B23: 22 | C23: 租佃／欠租 | D23: 领票／欠租字 | E23: 3 嘉道（1796-1850） | F23: 道光 | G23: 道光玖年二月 日 | H23: 1829 | I23: 陈国远 | J23: 男 | K23: 欠租佃户，立票人 | L23: 未写名（收租业主，应即黄隆贯） | M23: 不详 | O23: 田 | P23: 田 | Q23: 旧欠租米分期偿还，期限延至乙未（1835）、丙申（1836）年 | R23: 旧欠租米共叁石柒斗余 | T23: 米谷 | V23: 叶宜全（保票人） | W23: 吴青山（代字） | X23: 无官印 | Y23: 过期每斗每月加利米叁合，系保票代赔无词 | Z23: 同纸三张欠租票，均道光玖年二月立：1) 旧欠租米壹石壹斗正，期至乙未年八月□日送仓；2) 旧欠租米壹石零玖升正，期至乙未年拾二月二十日送仓；3) 旧欠租米壹石伍斗贰升叁合叁勺，期至丙申年十二月二十日送仓 | AA23: 与 Folder 21 同日所立同格式欠租票，但还期推至六七年之后，构成一个长期分期偿还计划；同一保人、同一代字人。 | AB23: 目录把叶宜全列作 Buyer，实为保票人 | AC23: 高 | AD23: 第一票送仓日期字不全 | AE23: 1 | AF23: Seller: 陳國遠（立票人） [CHENG Guoyuan] -- Buyer: 葉宜全（保票人） [YE Yiquan] -- Personal | AG23: 1829 | AH23: 查看原件 | AI23: 31735066266572
A24: 1 | B24: 23 | C24: 租佃／欠租 | D24: 领票／欠租字 | E24: 3 嘉道（1796-1850） | F24: 道光 | G24: 道光九年七月廿八日 | H24: 1829 | I24: 黄隆贯 | J24: 男 | K24: 收租业主，立收字 | L24: 陈国远 | M24: 不详 | O24: 田 | P24: 田 | Q24: 收到陈国远旧欠租米 | R24: 旧欠租米壹石肆斗正 | T24: 米谷 | W24: 黄隆贯（自立） | X24: 无官印；钤黄隆贯私章及两方菱形骑缝章 | AA24: 证实 Folder 21、22 欠租票的债权人就是黄隆贯；黄隆贯从嘉庆十年（Folder 15）到道光九年一直向陈国远家收租。 | AC24: 高 | AE24: 1 | AF24: Seller: 黃隆貫 [HUANG Longguan] -- Buyer: 陳國遠 [CHEN Guoyuan] -- Place: unknown -- Personal | AG24: 1829 | AH24: 查看原件 | AI24: 31735066237722
A25: 1 | B25: 24 | C25: 分家书 | D25: 分家书／阄书 | E25: 3 嘉道（1796-1850） | F25: 道光 | G25: 道光拾柒年拾月 日 | H25: 1837 | I25: 义容（主阄父） | J25: 男 | K25: 父主持阄分；六子：长男良和（诗房）、次男良春（书房）、三男良吉（易房）、四男良禄（礼房）、五男良科（春房）、六男良提(?)（秋房） | L25: 六子：良和、良春、良吉、良禄、良科、良提(?) | M25: 不详 | N25: 养膳田坐产十七都曲山地，土名大垅等处 | O25: 屋／厝 | P25: 屋＋田 | Q25: 房屋按房分配：诗房上厝本厝左边正横厝第一直前壹橔，书房同第一直后壹橔，易房第贰直前壹橔，礼房第贰直后壹橔，春房第□直前壹橔，秋房第□直后壹橔；父抽养膳民田根壹号，受种贰斗，载租早米捌斗伍管，禾米肆斗，纳在县中侯处 | V25: 叔义安（公见）；兄良光（公见）；王绳喜（母舅）；毛元斯（表叔） | W25: 陈明金（代笔叔公） | X25: 无官印（私家文书） | Z25: 线装阄书一册共11页：封面'道光拾柒年拾月吉日立'；序文（父义容述兄弟和宜防争、请宗亲公见、按诗书易礼春秋六房阄分）；父抽养膳田一号；诗、书、易、礼、春、秋六房各一页，分得上厝本厝左边正横厝某直前／后壹橔；末页落款及立阄人、公见、母舅、表叔、代笔署名 | AA25: 以《诗》《书》《易》《礼》《春》《秋》六字为六房阄号，是典型的儒雅化阄书；对房屋按'直''橔'精细切分。目录标为 Folder 24-1，可能还有同组其它册。 | AB25: 目录 Owner 作'义容'，未写姓；阄书亦未见姓氏 | AC25: 中 | AD25: 六男名'良提'、春秋两房的'第□直'数字存疑；养膳田数量字存疑；序文未逐字录 | AE25: 11 | AF25: Owner: 義容 [Yirong] -- Place: unknown -- Personal | AG25: 1837 | AH25: 查看原件 | AI25: 31735066267976
A26: 1 | B26: 25 | C26: 典当／胎借 | D26: 典契 | E26: 3 嘉道（1796-1850） | F26: 道光 | G26: 道光拾玖年十壹月 日 | H26: 1839 | I26: 叶国佑 | J26: 男 | K26: 阄分己分；胞兄国佐在见，胞侄世枝、世桄仝见 | L26: 大绅（绅） | M26: 古田县 | N26: 坐址九都九保太平洋地方，土名俗呌里洋中坂 | O26: 田 | P26: 田 | Q26: 福屯田壹号，该田肆亩贰分，乡正年收租早谷陆石小秤足；粮系屯课，推入绅户 | R26: 田价银陆拾伍两纹广整；外有中用钱捌百文 | S26: 65 | T26: 银两 | U26: 周昌烈(?)（中人） | V26: 胞兄叶国佐（在见）；胞侄叶世枝、叶世桄（仝见） | X26: 钤红色斜方官印三方（红契） | Y26: 约限伍年满足外，任佑备价取赎，不论年限，绅不得揽留；赎田每两折钱捌百捌拾文 | AA26: 典的是'屯田'（屯课），粮由'九都叶步增福屯'户内推出；并缴原典契壹纸、尽契壹纸、借字壹纸共肆纸。契末大字'典契(?)'。受典人只写'大绅'，可能是对士绅的敬称。 | AB26: 目录作卖契、买主'绅'；契文为典契 | AC26: 中 | AD26: 中人名、租谷数存疑；'大绅'是否人名存疑 | AE26: 1 | AF26: Seller: 葉國佑 [YE Guoyou] -- Buyer: 紳 [SHEN] -- Place: 福建省古田縣 [Fujian Sheng Gutian Xian] -- Government | AG26: 1839 | AH26: 查看原件 | AI26: 31735066266515
A27: 1 | B27: 26 | C27: 分家书 | D27: 分家书／阄书 | E27: 3 嘉道（1796-1850） | F27: 道光 | G27: 道光贰拾年□月 日 | H27: 1840 | I27: 林氏（母） | J27: 女 | K27: 寡母主持为二子阄分；长男国诗、次男国书 | L27: 长男国诗、次男国书（福、禄二房） | M27: 不详 | N27: 土名半塘垅、虎啸、马路边、白龙山等处（县未写） | O27: 田 | P27: 田＋屋＋池塘＋坟地 | Q27: 祖遗山场屋宇田园：养膳田（郭大珠早晚租谷陆百肆拾斤等）；大厅、后厅、天井、左右披屋、大厝左边楼等房屋；田（郭其泉、陈肇祺、周雍美等佃，租谷数百斤至壹千余斤）；门前大池壹口（鱼利两房轮收）；陈兆熙造坟等 | V27: 林长宾(?)（在见）；勇(?)春(?)（在见）；陈必祥；杨能波(?)；李仕□；林文愿(?) | W27: 李龙泉(?) | X27: 无官印 | AA27: 母亲（林氏）作为立阄人主持分家，体现寡母在家产分配中的权威；池塘、鱼利、粮色按年轮值；纸张多处虫蛀成洞。契末大字'大长发其祥'。 | AB27: 目录 Owner 作'林氏'；契文为'母林氏' | AC27: 低 | AD27: 纸张大面积虫蛀，许多田名、租额、见人姓名残缺；月份不清 | AE27: 1 | AF27: Owner: 林氏 [LIN Shi] -- Personal | AG27: 1840 | AH27: 查看原件 | AI27: 31735066266259
A28: 1 | B28: 27 | C28: 其他 | D28: 其他（禁鸦片保甲门牌） | E28: 3 嘉道（1796-1850） | F28: 道光 | G28: 道光贰拾年分 | H28: 1840 | I28: 闽清县正堂徐（知县） | J28: 官方 | K28: 县官颁发的保甲门牌 | L28: 陈行典(?)（家长） | M28: 闽清县 | N28: 闽清县上十七都□图 | O28: 其他／非土地 | P28: 其他（户籍门牌，非土地） | Q28: 家长陈行典(?)，不吸烟，年六十八岁，以耕田为业；子立崇，孙邦栋、邦腾、邦镇、邦增、邦煜、邦曾(?)、邦炽，曾孙元具；侄立训、立拱(?)，侄孙邦仪、邦夫(?)、邦佑；十家联保陈立灿等；牌正陈孝朗、副陈孝炳；甲正余邦干、副黄金波 | X28: 木刻印刷官颁门牌，盖有长方形墨印 | AA28: 鸦片战争当年（道光二十年）闽清县'查禁鸦片派保门牌'，逐户登记是否吸烟，并引新例：限一年六个月内戒除，逾限者拟绞监候，十家联保连坐。是土地契约外的社会控制史料。 | AB28: 目录 Owner 作'陈行典'，门牌家长名字'行典'字迹模糊 | AC28: 中 | AD28: 家长名、部分孙辈名字为手写小字，存疑；图号空白 | AE28: 1 | AF28: Owner: 陳行典 [CHENG Xingdian] -- Place: 福建省閩清縣 [Fujian Sheng Minqing Xian] -- Personal | AG28: 1840 | AH28: 查看原件 | AI28: 31735066266408
A29: 1 | B29: 28 | C29: 买卖（卖／卖断） | D29: 卖契 | E29: 3 嘉道（1796-1850） | F29: 道光 | G29: 道光贰拾年八月 日 | H29: 1840 | I29: 刘孝良（仝弟刘孝清） | J29: 男 | K29: 兄弟同立；承祖遗手置有税山；声明系良、清承祖遗，与别房无干 | L29: 林高满 | M29: 闽清县 | N29: 十四都重坑地方，土名桔(?)模(?)坪等处；又土名深田址 | O29: 山林 | P29: 山／山林＋屋＋地基／屋地 | Q29: 税山壹所（内抽出黄(?)甜竹林壹所），四至：上至顶、下至田、左至哲焕(?)失路直上、右至胡家墓仑中宫直上；又卖税山土名深田址，界上下左右水流窝；前坂厝屋壹扇左边等处（中宫直上至椽桁、下至地基）及右边园坪壹半、上下余地；山场松杉什木、笋竹、桐茶等 | R29: 卖出价钱壹拾壹千伍百文；民国验契按卖价拾贰圆，纳税肆角捌分 | S29: 11500 | T29: 铜钱 | U29: 朱明贵（代字中） | V29: 宗兄佑志（在见）；仝弟刘孝清 | W29: 朱明贵（代字中） | X29: 白契上贴民国印花税票；附民国二十六年福建省财政厅官契纸（闽清县印、财政厅印，契税4%） | Y29: 卖断；林家永远入宅住居，刘家不敢异言；如刘家另有吉地，林家不得借批阻；山租钱每年壹百文交还刘家 | Z29: 1) 分卖山契，道光贰拾年八月，刘孝良仝弟孝清将十四都重坑税山一所及庄基地、厝屋卖与林高满，价钱壹拾壹千伍百文；契上贴民国印花税票数枚；2) 福建省财政厅颁发卖契纸（官契纸），中华民国二十六年五月二十七日，闽清县，业主林高满，不动产种类税山，坐落重坑，面积一所，卖价拾贰圆，应纳税银肆角捌分，出卖人刘孝良，中证人朱明贵，立契年月填'道光二十年八月' | AA29: 清道光白契在近百年后（1937）被持去补税并换领民国官契纸，价钱折为法币拾贰圆。卖主保留每年山租钱壹百文。契首大字'大进益(?)'。 | AB29: 目录年代1840–1937与正契、官契纸吻合 | AC29: 中 | AD29: 部分土名（桔模坪、黄甜竹林）及四至人名存疑；官契纸字号不清 | AE29: 2 | AF29: Seller: 劉孝良 [LIU Xiaoliang] -- Buyer: 林高滿 [LIN Gaoman] -- Place: 福建省閩清縣 [Fujian Sheng Minqing Xian] -- Government | AG29: 1840 to 1937 | AH29: 查看原件 | AI29: 31735066266556
A30: 1 | B30: 29 | C30: 典当／胎借 | D30: 胎借／借字 | E30: 3 嘉道（1796-1850） | F30: 道光 | G30: 道光贰拾壹年辛丑二月十六日 | H30: 1841 | I30: 林忠、林荣（兄弟） | J30: 男 | K30: 兄弟同立当季字；会份系自己续买赖绍福名下 | L30: 赖荣松（先生） | M30: 不详 | O30: 其他／非土地 | P30: 其他（关帝会会份） | Q30: 关帝季（神明会）式大股，原由赖绍福名下续买 | R30: 佛银陆大圆正，共重□□ | S30: 6 | T30: 番银 | V30: 赖祥福（在场见人） | W30: 弟(?)荣（执笔） | X30: 无官印；纸张四周裱有蓝色织锦边 | Y30: 每员每月行息式分，其银的限对期之日并本息一足兑还；如违，任凭银主将季起取，改名饮酒分承 | AA30: 抵押品不是土地而是'关帝季'会份（神明会股份），违约则债主可改名入会'饮酒分承'；当日交付买季契二纸。用'佛银大圆'（西班牙银元）计价。 | AB30: 目录作卖主/买主，实为以会份作抵押的当借字 | AC30: 高 | AD30: 执笔人名字存疑；重量数字不清 | AE30: 1 | AF30: Seller: 林忠 [LIN Zhong] and 林榮[LIN Rong]-- Buyer: 賴榮松 [LAI Rongsong] -- Place: Unknown -- Personal | AG30: 1841 | AH30: 查看原件 | AI30: 31735066266457
A31: 1 | B31: 30 | C31: 合同／约字 | D31: 合同 | E31: 3 嘉道（1796-1850） | F31: 道光 | G31: 道光贰拾贰年拾贰月念五日 | H31: 1842 | I31: 黄惟裕、黄惟岑 | J31: 男 | K31: 两家田池相连致口角争端，经亲友公议立合约 | M31: 不详 | O31: 田 | P31: 田＋池塘 | Q31: 一家掌田、一家掌池；田边在池边者递年池水润田，约至春三月末为限；其池土岑内应半埕(?)；侯池主幸(?)池之日挑回应用 | R31: 池土公估价钱叁百伍拾文（田主再买池土） | S31: 350 | T31: 铜钱 | V31: 黄孝甲（公亲）；黄继书（公亲）；黄廉镜（公亲）；黄廉阜（公亲）；黄绍度（公亲） | W31: 黄继书（代笔） | X31: 无官印 | AA31: 同族两家调处田与池塘用水、挖池土纠纷的合约，规定放水时限、池土归属和修理责任；左端有骑缝大字'合同二纸(?)'半字。 | AB31: 目录只列卖主，实为调解合约 | AC31: 中 | AD31: 岑内应半埕''幸池'等词语存疑 | AE31: 1 | AF31: Seller: 黃維裕 [HUANG Weiyu] and 黃維岑[HUANG Weicen] -- Personal | AG31: 1842 | AH31: 查看原件 | AI31: 31735066266366
A32: 1 | B32: 31 | C32: 典＋找贴 | D32: 典契＋找贴契／贴尽契（凑断契） | E32: 3 嘉道（1796-1850） | F32: 道光 | G32: 道光贰拾肆年贰月吉日（典）；道光贰拾伍年陆月吉日（凑断） | H32: 1844 | I32: 林厚成（同胞弟厚禄、厚祥，胞侄春新） | J32: 男 | K32: 承父在日手置店屋；兄弟叔侄同立，知契母郭氏，胞嫂陈氏画押 | L32: 叶家（叶成） | M32: 侯官县 | N32: 侯邑魁辅铺地方 | O32: 店屋 | P32: 店屋 | Q32: 店屋壹栋，坐南朝北，前进五柱、天井、左右过水、第二进五柱、过水相连、后进叁柱，连楼阁地坪、门窗户扇、井厕一切；四至：前至官街、后至河、左至叶家屋、右至金(?)家屋 | R32: 典价银陆拾伍两正＋修理银伍两共成柒拾两；凑断银叁拾两，共成壹百两正，正纹广九七色 | S32: 100 | T32: 银两 | U32: 林道吉 | V32: 知契母郭氏；胞嫂陈氏；胞弟厚祥；胞弟厚禄；胞侄春新；胞孀李氏（在见）；陈元海（在见） | W32: 蒋则荣 | X32: 契面钤多枚朱红大方印（疑为侯官县印，红契）；地保'勤慎'戳记（侯字第拾玖号城内，魁辅铺地保）；1950年代台江区私房改造办公室'国家经租'印及福州土地登记处登记章 | Y32: 典契约伍年为限，限满听备价取赎；凑断后声明永断葛藤，不得言赎言凑 | Z32: ①典契：道光贰拾肆年贰月，林厚成同胞弟等将店屋典与叶家，价银陆拾伍两＋修理银伍两共柒拾两，约伍年为限取赎；②凑断契：道光贰拾伍年陆月，林厚成仝胞弟厚禄、厚祥、胞侄春新将该店屋凑断与叶家，再得价银叁拾两，连前共成壹百两正；凑断契上另加盖1950年代'国家经租 台江区人民委员会私房改造办公室'蓝印及'福州土地登记处'红色登记章（义字230号） | AA32: 同一店屋先典后凑断，两份契纸并存，凑断契注明缴原典契一纸；1950年代被盖'国家经租'章，反映社会主义私房改造。与 Folder 34（31735066267802）为同一交易的契尾与民国验契。 | AB32: 目录作卖契（Seller/Buyer），实为典契加凑断契；目录未列胞弟厚禄为'厚禄'外另有胞侄春新 | AC32: 中 | AD32: 典契右至'金(?)家屋'；代笔'蒋则荣'末字；凑断契左侧残缺，中人等签押可能缺失 | AE32: 2 | AF32: Seller: 林厚成 [LIN Houcheng] and 林厚祿 [Lin Houlu] and 林厚祥 [Lin Houxiang] -- Buyer: 葉成 [YE Cheng] -- Place: 福建省侯官縣 [Fujian Sheng Houguan Xian] -- Personal | AG32: 1844 to 1845 | AH32: 查看原件 | AI32: 31735066266374
A33: 1 | B33: 32 | C33: 契尾／验契 | D33: 契尾 | E33: 3 嘉道（1796-1850） | F33: 道光 | G33: 道光贰拾玖年拾贰月 日 | H33: 1849 | I33: 林元梁(?) | J33: 男 | K33: 契尾填写'业户林元昂(?)买林元梁(?)山一所' | L33: 林元昂(?) | M33: 古田县 | N33: 古田县，本处土名□□、对面山等处 | O33: 山林 | P33: 山／山林 | Q33: 山一所，坐落本处土名□□、对面山等处 | R33: 用价银贰拾伍两陆钱叁分；纳税银□两柒钱陆分玖厘 | S33: 25.63 | T33: 银两 | X33: 福建布政使司颁刻印契尾，布字第捌千贰百捌拾伍号，右给古田县业户；钤多枚官印（骑缝） | AA33: 官颁契尾，仅存契尾不见原契；契尾顶部骑缝处手书号数'捌千贰百捌拾伍'。 | AB33: 目录业主作'林元鼎'，图像上业户名末字更像'昂' | AC33: 中 | AD33: 业户名'林元昂/鼎'、卖主'林元梁'末字、纳税银两数首字均不确定；土名不清 | AE33: 1 | AF33: Owner: 林元鼎 [LIN Yuanding] -- Place: 福建省古田縣 [Fujian Sheng Gutian Xian] -- Government | AG33: 1849 | AH33: 查看原件 | AI33: 31735066237417
A34: 1 | B34: 33 | C34: 典当／胎借 | D34: 卖契（田根，限期可赎） | E34: 3 嘉道（1796-1850） | F34: 道光 | G34: 道光叁拾年玖月吉日 | H34: 1850 | I34: 林世奕 | J34: 男 | K34: 承父阄分份下民田根；知契母萧氏 | L34: 林（名空缺） | M34: 侯官县 | N34: 侯邑三十八都白龙洋地方，土名园坵、深田 | O34: 田根 | P34: 田根 | Q34: 民田根壹号大小伍坵，土名园坵，计官丈贰亩零，年载租谷叁百贰拾肆筋平秤纳在周家；更有壹号土名深田，计官丈壹亩伍分，年载禾租谷壹百贰拾筋平秤纳在面主李家 | R34: 田根价银贰百两正，平戥九七色 | S34: 200 | T34: 银两 | U34: 翁太湖 | V34: 知契母萧氏；胞兄世美（在见）；胞兄世乔(?)（在见）；胞弟世廷 | W34: 王凤鸣 | X34: 无官印（白契） | Y34: 约伍年为限，限满听世奕备价照契面银两取赎；如未取赎仍听买主管业 | AA34: 典型一田二主：卖的是田根，租谷分别纳给周家和面主李家；买主仅写'林'字留空，契末大书'大熟'。另缴原契壹纸，共成贰纸。 | AC34: 高 | AD34: 在见'世乔'一名排列不清 | AE34: 1 | AF34: Seller: 林世奕 [LIN Shiyi] -- Buyer: 林 [LIN] -- Place: 福建省侯官縣 [Fujian Sheng Houguan Xian] -- Personal | AG34: 1850 | AH34: 查看原件 | AI34: 31735064607868
A35: 1 | B35: 33A | C35: 买卖（卖／卖断） | D35: 卖断契 | E35: 3 嘉道（1796-1850） | F35: 道光 | G35: 道光叁拾年拾壹月 日 | H35: 1850 | I35: 游振梅 | J35: 男 | K35: 道光十五年间用价买断陈□□店屋，今转卖；知契母张氏 | L35: 杨家（杨坤贞） | M35: 闽县 | N35: 闽邑嘉崇里八(?)图壹甲四保铺洲(?)堤街地方 | O35: 店屋 | P35: 店屋 | Q35: 店屋壹座，前系店面伍柱壹栋，后天井、披屋叁栋叁堵，又后进一所，楼阁横廊、板地杆廊一切俱全；四至：前至官街、后至江、左至郑家墙、右至陈家 | R35: 卖断出价银玖拾陆两，正纹库平；民国契纸载价壹百捌拾壹元 | S35: 96 | T35: 银两 | U35: 杨隆魁；郑廷源 | V35: 知契母张氏；弟振潮（在见）；弟振文；侄连提；出继男连芳；胞母舅(?)张昌□；胞姊黄游氏 | W35: 周绅杨(?) | X35: 清代契尾（闽县，官印）；民国十二年新颁卖契纸（新颁契纸印）；民国十四年(?)福建财政厅验税契照；光绪年间朱色注记 | Y35: 卖断，永断葛藤，不得言赎 | Z35: ①卖断契：道光叁拾年拾壹月，游振梅将店屋卖断与杨家；②契尾：闽县，□万壹千壹百肆拾玖号，右给闽县业户杨坤贞，载'杨坤贞买游振梅屋一所'；③民国新颁卖契纸：中华民国十二年五月四日，买主杨坤贞、卖主游振梅、中人杨隆魁，不动产种类店屋，卖价壹百捌拾壹元，应纳税额捌元贰角叁占(?)，原契'清红'，立契年月道光卅年十一月，坐落嘉崇里□保铺；④验税契照：中华民国十四年(?)五月，福建财政厅给业户杨坤贞；原契另有光绪拾壹年伍月、光绪廿一年六月红色注记戳 | AA35: 一件之内串连清代卖断契、契尾、民国换契与验契四种文书，跨越1850-1925年；民国换契时按银元重估价格。契末书'长发其祥'。 | AC35: 中 | AD35: 地名'八图''洲堤街'、陈姓原主名、代字人名、民国验契年份（十四年?）与税额均存疑 | AE35: 1 | AF35: Seller: 游振梅 [pin yin] -- Buyer: 楊坤貞 [pin yin] -- Place: 福建省閩縣 [Fujian Sheng Min Xian] -- Personal | AG35: 1850 to 1923 | AH35: 查看原件 | AI35: 31735068223258
A36: 1 | B36: 34 | C36: 契尾／验契 | D36: 契尾＋验契凭证 | E36: 4 咸同光宣（1851-1911） | F36: 咸丰 | G36: 咸丰肆年□月（契尾）；中华民国贰年拾贰月（契单） | H36: 1854 | I36: 林厚成 | J36: 男 | K36: 原卖主（道光二十五年凑断） | L36: 叶成 | M36: 侯官县 | N36: 侯官县魁辅铺／闽侯县魁辅里地方 | O36: 店屋 | P36: 店屋 | Q36: 店屋壹栋，坐南向北 | R36: 价银壹百两；纳税银叁两 | S36: 100 | T36: 银两 | U36: 林道吉 | V36: 陈元海（证） | W36: 蒋则荣 | X36: 布政司契尾（侯官县官印）；民国二年福建国税厅筹备处卖断契单（验契，纸价壹元）；地保戳记 | Z36: ①契尾：咸丰肆年□月，布字壹万玖百玖号，右给侯官县业户叶成，载'业户叶成买林厚成等店屋'，用价银壹百两，纳税银叁两；契尾粘连原典契末段（代笔蒋则荣、中友林道吉、地保'勤慎'戳、'大进'字样）；②卖断契单：福建国税厅筹备处颁，中华民国贰年拾贰月，验字第八万四千四百十七号，载业户叶成于清道光贰拾伍年陆月买受林厚成店屋壹栋，坐落闽侯县魁辅里，价银壹百两，证人陈元海；另有民国十五年三月九日朱色注记 | AA36: 与 Folder 31（31735066266374）为同一店屋的后续官方文书：交易1845年完成，1854年才投税领契尾，1913年再验契。 | AB36: 目录作1854-1913，与图像相符 | AC36: 中 | AD36: 契尾月份、号数个别字不清 | AE36: 2 | AF36: Owner: 葉成 [YE Cheng] --Seller: 林厚成 [LIN Houcheng] -- Buyer: 葉成 [YE Cheng] -- Place: 福建省閩侯縣和侯官縣[Fujian Sheng Minhou Xian and Houguan Xian] -- Government | AG36: 1854 to 1913 | AH36: 查看原件 | AI36: 31735066267802
A37: 1 | B37: 35 | C37: 买卖（卖／卖断） | D37: 卖断契 | E37: 4 咸同光宣（1851-1911） | F37: 咸丰 | G37: 咸丰八年十二月吉日 | H37: 1858 | I37: 陈士曾 | J37: 男 | K37: 原自己阄分份下根面全田；卖与堂兄 | L37: 陈士庆（堂兄） | M37: 侯官县 | N37: 侯邑廿八都富村地方，土名过圳、洋满池等处 | O37: 田（根面全） | P37: 田（根面全）＋池塘 | Q37: 根面全田叁号：土名过圳计官丈壹亩捌分，粮挂壹亩捌分；土名洋满池官丈肆分零，粮挂本都四图九甲陈纯户下；另一号粮挂本都四图四甲陈孟寿户下；年纳租谷叁百肆拾伍筋；内有池壹口，其水永听律派足用 | R37: 南街铜钱壹百叁拾千文正 | S37: 130000 | T37: 铜钱 | U37: 陈开文（族叔） | V37: 胞弟士美（在见） | W37: 卢(?)志高 | X37: 契面钤朱红方印数枚（疑为侯官县印，红契） | Y37: 卖断，永断葛藤，不得别生枝节 | AA37: 兄弟间根面全田卖断，粮户分挂于陈纯户、陈孟寿户，可见户籍粮户与实际业主分离；价以铜钱计，单位'千文'。契末'永远为业'。 | AB37: 目录地点作unknown，契文明写侯邑廿八都富村 | AC37: 中 | AD37: 第三号田土名及部分亩分、代字人首字不清；price_amount按文计 | AE37: 1 | AF37: Seller: 陳士曾 [CHEN Shizeng] -- Place: unknown -- Government | AG37: 1858 | AH37: 查看原件 | AI37: 31735066267885
A38: 1 | B38: 36 | C38: 买卖（卖／卖断） | D38: 卖断契 | E38: 4 咸同光宣（1851-1911） | F38: 同治 | G38: 同治壬戌元年柒月 日 | H38: 1862 | I38: 张华富 | J38: 男 | K38: 承祖遗下 | L38: 程金宝 | M38: 不详 | N38: 田里南坑，土名凤坑仔 | O38: 山林 | P38: 山／山林 | Q38: 皮骨茶山壹片（连竹、茶、杂木）；四至：上至岗顶、下至田、左至本张宅分水为界、右至亦本张分水为界 | R38: 时值价铜钱捌仟五百文正 | S38: 8500 | T38: 铜钱 | U38: 张华春（为中人）；张喜孙（说谕人） | V38: 张华应（在见人） | W38: 詹王佐 | X38: 无官印（白契） | Y38: 卖断，永远管业，不得阻执 | AA38: 皮骨（山面山底）一并卖断；声明上手契一时不及寻出，日后寻出不堪行用。契尾大书'卖断契'。 | AC38: 高 | AD38: 地名'田里'所属县份无法判断 | AE38: 1 | AF38: Seller: 张华富 [ZHANG Huafu] -- Personal | AG38: 1862 | AH38: 查看原件 | AI38: 31735064607454
A39: 1 | B39: 37 | C39: 典当／胎借 | D39: 典契（田根） | E39: 4 咸同光宣（1851-1911） | F39: 同治 | G39: 同治元年八月吉日 | H39: 1862 | I39: 杨兆通 | J39: 男 | K39: 承父阄分份下民田根 | L39: 林（名空缺） | M39: 侯官县 | N39: 侯邑三十八都白龙坛路地方，土名鲫鱼坵 | O39: 田根 | P39: 田根＋池塘 | Q39: 民田根壹号，计官丈贰亩伍分，大小三坵、池壹口，共肆坵；年纳面主王家早晚租谷叁百伍拾筋平秤 | R39: 田根价银贰百捌拾叁两伍钱正；取赎每两银折铜钱柒百伍拾文 | S39: 283.5 | T39: 银两 | U39: 蔡书波（中友）；李兆桐 | V39: 胞弟兆如；堂侄能波；刘朝达（在见） | W39: 李肇(?)松 | X39: 无官印（白契） | Y39: 叁年为限，限满听兆通备价照契面银取赎，每两折钱柒百伍拾文；约赎田以冬至前为期 | AA39: 并缴上手杨昌岳(?)典契、邦铭尽契、海武断契共成肆纸，可见此田根层层转手；与 Folder 33 林世奕契同在三十八都白龙一带，买主同为空名'林'，疑为同一林姓置产人。 | AB39: 目录作Seller，实为典契 | AC39: 中 | AD39: 上手契人名'昌岳''邦铭''海武'及代笔名中字不确定 | AE39: 1 | AF39: Seller: 楊兆通 [YANG Zhaotong] -- Buyer: 林 [LIN] -- Personal | AG39: 1862 | AH39: 查看原件 | AI39: 31735064607728
A40: 1 | B40: 38 | C40: 找贴／凑断 | D40: 找贴契／贴尽契（增找字） | E40: 4 咸同光宣（1851-1911） | F40: 同治 | G40: 同治贰年拾二月 日 | H40: 1863 | I40: 黄志林 | J40: 男 | K40: 自己手卖有田骨，前契载明 | L40: 刘子祥 | M40: 不详 | N40: （前契载明，本字未写） | O40: 田根 | P40: 田根 | Q40: 田骨，坐落、米数、银两俱载前契 | R40: 增找出洋银叁两正；外用中见礼洋银壹钱正 | S40: 3 | T40: 银元／大洋 | U40: 蔡廷有（为中在见人）；刘贵年(?)（为中在见人） | W40: 刘立忠(?) | X40: 无官印；立字人及中见、代笔各钤小私章 | Y40: 增找之后任凭买主前去收租管业，卖者再无言增言找 | AA40: 托原中刘谕向买主增找，属卖后加找；各签名处钤有朱色私章，较少见。 | AB40: 目录买主作'刘子珜'，契文似'刘子祥'；目录无日期，契为同治二年 | AC40: 中 | AD40: 原中名、为中人第二名及代笔名存疑 | AE40: 1 | AF40: Seller: 黃志林 [HUANG Zhilin] -- Buyer: 劉子珜 [LIU Ziyang] -- Personal | AH40: 查看原件 | AI40: 31735066267448
...

Sheet 统计
A1: 统计（公式随“总表”实时计算；在总表中修正后这里会自动更新）
A3: 一、文书大类 | F3: 八、交易价格（仅买卖、典当、找贴类文书；按币种 × 时期）
A4: 类别 | B4: 件数 | C4: 占比 | F4: 注：同一币种内交易物大小差异很大（一间屋到数亩田），均值只作粗略参考；找贴类价格是加价部分而非全价。
A5: 买卖（卖／卖断） | B5: =COUNTIF(总表!$C$2:$C$235,A5) -> 68 | C5: =IFERROR(B5/COUNTA(总表!$AI$2:$AI$235),0) -> 0.29059829 | F5: 币种 | G5: 时期 | H5: 件数 | I5: 平均 | J5: 最低 | K5: 最高
A6: 典当／胎借 | B6: =COUNTIF(总表!$C$2:$C$235,A6) -> 40 | C6: =IFERROR(B6/COUNTA(总表!$AI$2:$AI$235),0) -> 0.17094017 | F6: 银两 | G6: 2 清前期（1644-1795） | H6: =SUMPRODUCT(COUNTIFS(总表!$T$2:$T$235,$F6,总表!$E$2:$E$235,$G6,总表!$C$2:$C$235,{"买卖（卖／卖断）","典当／胎借","找贴／凑断","典＋找贴"},总表!$S$2:$S$235,">0")) -> 9 | I6: =IFERROR(SUMPRODUCT(SUMIFS(总表!$S$2:$S$235,总表!$T$2:$T$235,$F6,总表!$E$2:$E$235,$G6,总表!$C$2:$C$235,{"买卖（卖／卖断）","典当／胎借","找贴／凑断","典＋找贴"},总表!$S$2:$S$235,">0"))/H6,"—") -> 18.022222 | J6: =IF(H6=0,"—",MIN(IF(COUNTIFS(总表!$T$2:$T$235,$F6,总表!$E$2:$E$235,$G6,总表!$C$2:$C$235,"买卖（卖／卖断）",总表!$S$2:$S$235,">0")=0,1E+99,_xlfn.MINIFS(总表!$S$2:$S$235,总表!$T$2:$T$235,$F6,总表!$E$2:$E$235,$G6,总表!$C$2:$C$235,"买卖（卖／卖断）",总表!$S$2:$S$235,">0")),IF(COUNTIFS(总表!$T$2:$T$235,$F6,总表!$E$2:$E$235,$G6,总表!$C$2:$C$235,"典当／胎借",总表!$S$2:$S$235,">0")=0,1E+99,_xlfn.MINIFS(总表!$S$2:$S$235,总表!$T$2:$T$235,$F6,总表!$E$2:$E$235,$G6,总表!$C$2:$C$235,"典当／胎借",总表!$S$2:$S$235,">0")),IF(COUNTIFS(总表!$T$2:$T$235,$F6,总表!$E$2:$E$235,$G6,总表!$C$2:$C$235,"找贴／凑断",总表!$S$2:$S$235,">0")=0,1E+99,_xlfn.MINIFS(总表!$S$2:$S$235,总表!$T$2:$T$235,$F6,总表!$E$2:$E$235,$G6,总表!$C$2:$C$235,"找贴／凑断",总表!$S$2:$S$235,">0")),IF(COUNTIFS(总表!$T$2:$T$235,$F6,总表!$E$2:$E$235,$G6,总表!$C$2:$C$235,"典＋找贴",总表!$S$2:$S$235,">0")=0,1E+99,_xlfn.MINIFS(总表!$S$2:$S$235,总表!$T$2:$T$235,$F6,总表!$E$2:$E$235,$G6,总表!$C$2:$C$235,"典＋找贴",总表!$S$2:$S$235,">0")))) -> 0.5 | K6: =IF(H6=0,"—",MAX(_xlfn.MAXIFS(总表!$S$2:$S$235,总表!$T$2:$T$235,$F6,总表!$E$2:$E$235,$G6,总表!$C$2:$C$235,"买卖（卖／卖断）",总表!$S$2:$S$235,">0"),_xlfn.MAXIFS(总表!$S$2:$S$235,总表!$T$2:$T$235,$F6,总表!$E$2:$E$235,$G6,总表!$C$2:$C$235,"典当／胎借",总表!$S$2:$S$235,">0"),_xlfn.MAXIFS(总表!$S$2:$S$235,总表!$T$2:$T$235,$F6,总表!$E$2:$E$235,$G6,总表!$C$2:$C$235,"找贴／凑断",总表!$S$2:$S$235,">0"),_xlfn.MAXIFS(总表!$S$2:$S$235,总表!$T$2:$T$235,$F6,总表!$E$2:$E$235,$G6,总表!$C$2:$C$235,"典＋找贴",总表!$S$2:$S$235,">0"))) -> 63
A7: 契尾／验契 | B7: =COUNTIF(总表!$C$2:$C$235,A7) -> 37 | C7: =IFERROR(B7/COUNTA(总表!$AI$2:$AI$235),0) -> 0.15811966 | F7: 银两 | G7: 3 嘉道（1796-1850） | H7: =SUMPRODUCT(COUNTIFS(总表!$T$2:$T$235,$F7,总表!$E$2:$E$235,$G7,总表!$C$2:$C$235,{"买卖（卖／卖断）","典当／胎借","找贴／凑断","典＋找贴"},总表!$S$2:$S$235,">0")) -> 9 | I7: =IFERROR(SUMPRODUCT(SUMIFS(总表!$S$2:$S$235,总表!$T$2:$T$235,$F7,总表!$E$2:$E$235,$G7,总表!$C$2:$C$235,{"买卖（卖／卖断）","典当／胎借","找贴／凑断","典＋找贴"},总表!$S$2:$S$235,">0"))/H7,"—") -> 95 | J7: =IF(H7=0,"—",MIN(IF(COUNTIFS(总表!$T$2:$T$235,$F7,总表!$E$2:$E$235,$G7,总表!$C$2:$C$235,"买卖（卖／卖断）",总表!$S$2:$S$235,">0")=0,1E+99,_xlfn.MINIFS(总表!$S$2:$S$235,总表!$T$2:$T$235,$F7,总表!$E$2:$E$235,$G7,总表!$C$2:$C$235,"买卖（卖／卖断）",总表!$S$2:$S$235,">0")),IF(COUNTIFS(总表!$T$2:$T$235,$F7,总表!$E$2:$E$235,$G7,总表!$C$2:$C$235,"典当／胎借",总表!$S$2:$S$235,">0")=0,1E+99,_xlfn.MINIFS(总表!$S$2:$S$235,总表!$T$2:$T$235,$F7,总表!$E$2:$E$235,$G7,总表!$C$2:$C$235,"典当／胎借",总表!$S$2:$S$235,">0")),IF(COUNTIFS(总表!$T$2:$T$235,$F7,总表!$E$2:$E$235,$G7,总表!$C$2:$C$235,"找贴／凑断",总表!$S$2:$S$235,">0")=0,1E+99,_xlfn.MINIFS(总表!$S$2:$S$235,总表!$T$2:$T$235,$F7,总表!$E$2:$E$235,$G7,总表!$C$2:$C$235,"找贴／凑断",总表!$S$2:$S$235,">0")),IF(COUNTIFS(总表!$T$2:$T$235,$F7,总表!$E$2:$E$235,$G7,总表!$C$2:$C$235,"典＋找贴",总表!$S$2:$S$235,">0")=0,1E+99,_xlfn.MINIFS(总表!$S$2:$S$235,总表!$T$2:$T$235,$F7,总表!$E$2:$E$235,$G7,总表!$C$2:$C$235,"典＋找贴",总表!$S$2:$S$235,">0")))) -> 8 | K7: =IF(H7=0,"—",MAX(_xlfn.MAXIFS(总表!$S$2:$S$235,总表!$T$2:$T$235,$F7,总表!$E$2:$E$235,$G7,总表!$C$2:$C$235,"买卖（卖／卖断）",总表!$S$2:$S$235,">0"),_xlfn.MAXIFS(总表!$S$2:$S$235,总表!$T$2:$T$235,$F7,总表!$E$2:$E$235,$G7,总表!$C$2:$C$235,"典当／胎借",总表!$S$2:$S$235,">0"),_xlfn.MAXIFS(总表!$S$2:$S$235,总表!$T$2:$T$235,$F7,总表!$E$2:$E$235,$G7,总表!$C$2:$C$235,"找贴／凑断",总表!$S$2:$S$235,">0"),_xlfn.MAXIFS(总表!$S$2:$S$235,总表!$T$2:$T$235,$F7,总表!$E$2:$E$235,$G7,总表!$C$2:$C$235,"典＋找贴",总表!$S$2:$S$235,">0"))) -> 310
A8: 粮单／税单 | B8: =COUNTIF(总表!$C$2:$C$235,A8) -> 25 | C8: =IFERROR(B8/COUNTA(总表!$AI$2:$AI$235),0) -> 0.10683761 | F8: 银两 | G8: 4 咸同光宣（1851-1911） | H8: =SUMPRODUCT(COUNTIFS(总表!$T$2:$T$235,$F8,总表!$E$2:$E$235,$G8,总表!$C$2:$C$235,{"买卖（卖／卖断）","典当／胎借","找贴／凑断","典＋找贴"},总表!$S$2:$S$235,">0")) -> 32 | I8: =IFERROR(SUMPRODUCT(SUMIFS(总表!$S$2:$S$235,总表!$T$2:$T$235,$F8,总表!$E$2:$E$235,$G8,总表!$C$2:$C$235,{"买卖（卖／卖断）","典当／胎借","找贴／凑断","典＋找贴"},总表!$S$2:$S$235,">0"))/H8,"—") -> 49.125 | J8: =IF(H8=0,"—",MIN(IF(COUNTIFS(总表!$T$2:$T$235,$F8,总表!$E$2:$E$235,$G8,总表!$C$2:$C$235,"买卖（卖／卖断）",总表!$S$2:$S$235,">0")=0,1E+99,_xlfn.MINIFS(总表!$S$2:$S$235,总表!$T$2:$T$235,$F8,总表!$E$2:$E$235,$G8,总表!$C$2:$C$235,"买卖（卖／卖断）",总表!$S$2:$S$235,">0")),IF(COUNTIFS(总表!$T$2:$T$235,$F8,总表!$E$2:$E$235,$G8,总表!$C$2:$C$235,"典当／胎借",总表!$S$2:$S$235,">0")=0,1E+99,_xlfn.MINIFS(总表!$S$2:$S$235,总表!$T$2:$T$235,$F8,总表!$E$2:$E$235,$G8,总表!$C$2:$C$235,"典当／胎借",总表!$S$2:$S$235,">0")),IF(COUNTIFS(总表!$T$2:$T$235,$F8,总表!$E$2:$E$235,$G8,总表!$C$2:$C$235,"找贴／凑断",总表!$S$2:$S$235,">0")=0,1E+99,_xlfn.MINIFS(总表!$S$2:$S$235,总表!$T$2:$T$235,$F8,总表!$E$2:$E$235,$G8,总表!$C$2:$C$235,"找贴／凑断",总表!$S$2:$S$235,">0")),IF(COUNTIFS(总表!$T$2:$T$235,$F8,总表!$E$2:$E$235,$G8,总表!$C$2:$C$235,"典＋找贴",总表!$S$2:$S$235,">0")=0,1E+99,_xlfn.MINIFS(总表!$S$2:$S$235,总表!$T$2:$T$235,$F8,总表!$E$2:$E$235,$G8,总表!$C$2:$C$235,"典＋找贴",总表!$S$2:$S$235,">0")))) -> 8.25 | K8: =IF(H8=0,"—",MAX(_xlfn.MAXIFS(总表!$S$2:$S$235,总表!$T$2:$T$235,$F8,总表!$E$2:$E$235,$G8,总表!$C$2:$C$235,"买卖（卖／卖断）",总表!$S$2:$S$235,">0"),_xlfn.MAXIFS(总表!$S$2:$S$235,总表!$T$2:$T$235,$F8,总表!$E$2:$E$235,$G8,总表!$C$2:$C$235,"典当／胎借",总表!$S$2:$S$235,">0"),_xlfn.MAXIFS(总表!$S$2:$S$235,总表!$T$2:$T$235,$F8,总表!$E$2:$E$235,$G8,总表!$C$2:$C$235,"找贴／凑断",总表!$S$2:$S$235,">0"),_xlfn.MAXIFS(总表!$S$2:$S$235,总表!$T$2:$T$235,$F8,总表!$E$2:$E$235,$G8,总表!$C$2:$C$235,"典＋找贴",总表!$S$2:$S$235,">0"))) -> 283.5
A9: 官方产权证照 | B9: =COUNTIF(总表!$C$2:$C$235,A9) -> 25 | C9: =IFERROR(B9/COUNTA(总表!$AI$2:$AI$235),0) -> 0.10683761 | F9: 银两 | G9: 5 北洋（1912-1927） | H9: =SUMPRODUCT(COUNTIFS(总表!$T$2:$T$235,$F9,总表!$E$2:$E$235,$G9,总表!$C$2:$C$235,{"买卖（卖／卖断）","典当／胎借","找贴／凑断","典＋找贴"},总表!$S$2:$S$235,">0")) -> 2 | I9: =IFERROR(SUMPRODUCT(SUMIFS(总表!$S$2:$S$235,总表!$T$2:$T$235,$F9,总表!$E$2:$E$235,$G9,总表!$C$2:$C$235,{"买卖（卖／卖断）","典当／胎借","找贴／凑断","典＋找贴"},总表!$S$2:$S$235,">0"))/H9,"—") -> 32 | J9: =IF(H9=0,"—",MIN(IF(COUNTIFS(总表!$T$2:$T$235,$F9,总表!$E$2:$E$235,$G9,总表!$C$2:$C$235,"买卖（卖／卖断）",总表!$S$2:$S$235,">0")=0,1E+99,_xlfn.MINIFS(总表!$S$2:$S$235,总表!$T$2:$T$235,$F9,总表!$E$2:$E$235,$G9,总表!$C$2:$C$235,"买卖（卖／卖断）",总表!$S$2:$S$235,">0")),IF(COUNTIFS(总表!$T$2:$T$235,$F9,总表!$E$2:$E$235,$G9,总表!$C$2:$C$235,"典当／胎借",总表!$S$2:$S$235,">0")=0,1E+99,_xlfn.MINIFS(总表!$S$2:$S$235,总表!$T$2:$T$235,$F9,总表!$E$2:$E$235,$G9,总表!$C$2:$C$235,"典当／胎借",总表!$S$2:$S$235,">0")),IF(COUNTIFS(总表!$T$2:$T$235,$F9,总表!$E$2:$E$235,$G9,总表!$C$2:$C$235,"找贴／凑断",总表!$S$2:$S$235,">0")=0,1E+99,_xlfn.MINIFS(总表!$S$2:$S$235,总表!$T$2:$T$235,$F9,总表!$E$2:$E$235,$G9,总表!$C$2:$C$235,"找贴／凑断",总表!$S$2:$S$235,">0")),IF(COUNTIFS(总表!$T$2:$T$235,$F9,总表!$E$2:$E$235,$G9,总表!$C$2:$C$235,"典＋找贴",总表!$S$2:$S$235,">0")=0,1E+99,_xlfn.MINIFS(总表!$S$2:$S$235,总表!$T$2:$T$235,$F9,总表!$E$2:$E$235,$G9,总表!$C$2:$C$235,"典＋找贴",总表!$S$2:$S$235,">0")))) -> 24 | K9: =IF(H9=0,"—",MAX(_xlfn.MAXIFS(总表!$S$2:$S$235,总表!$T$2:$T$235,$F9,总表!$E$2:$E$235,$G9,总表!$C$2:$C$235,"买卖（卖／卖断）",总表!$S$2:$S$235,">0"),_xlfn.MAXIFS(总表!$S$2:$S$235,总表!$T$2:$T$235,$F9,总表!$E$2:$E$235,$G9,总表!$C$2:$C$235,"典当／胎借",总表!$S$2:$S$235,">0"),_xlfn.MAXIFS(总表!$S$2:$S$235,总表!$T$2:$T$235,$F9,总表!$E$2:$E$235,$G9,总表!$C$2:$C$235,"找贴／凑断",总表!$S$2:$S$235,">0"),_xlfn.MAXIFS(总表!$S$2:$S$235,总表!$T$2:$T$235,$F9,总表!$E$2:$E$235,$G9,总表!$C$2:$C$235,"典＋找贴",总表!$S$2:$S$235,">0"))) -> 40
A10: 找贴／凑断 | B10: =COUNTIF(总表!$C$2:$C$235,A10) -> 14 | C10: =IFERROR(B10/COUNTA(总表!$AI$2:$AI$235),0) -> 0.05982906 | F10: 银两 | G10: 6 南京国民政府（1928-1948） | H10: =SUMPRODUCT(COUNTIFS(总表!$T$2:$T$235,$F10,总表!$E$2:$E$235,$G10,总表!$C$2:$C$235,{"买卖（卖／卖断）","典当／胎借","找贴／凑断","典＋找贴"},总表!$S$2:$S$235,">0")) -> 1 | I10: =IFERROR(SUMPRODUCT(SUMIFS(总表!$S$2:$S$235,总表!$T$2:$T$235,$F10,总表!$E$2:$E$235,$G10,总表!$C$2:$C$235,{"买卖（卖／卖断）","典当／胎借","找贴／凑断","典＋找贴"},总表!$S$2:$S$235,">0"))/H10,"—") -> 150 | J10: =IF(H10=0,"—",MIN(IF(COUNTIFS(总表!$T$2:$T$235,$F10,总表!$E$2:$E$235,$G10,总表!$C$2:$C$235,"买卖（卖／卖断）",总表!$S$2:$S$235,">0")=0,1E+99,_xlfn.MINIFS(总表!$S$2:$S$235,总表!$T$2:$T$235,$F10,总表!$E$2:$E$235,$G10,总表!$C$2:$C$235,"买卖（卖／卖断）",总表!$S$2:$S$235,">0")),IF(COUNTIFS(总表!$T$2:$T$235,$F10,总表!$E$2:$E$235,$G10,总表!$C$2:$C$235,"典当／胎借",总表!$S$2:$S$235,">0")=0,1E+99,_xlfn.MINIFS(总表!$S$2:$S$235,总表!$T$2:$T$235,$F10,总表!$E$2:$E$235,$G10,总表!$C$2:$C$235,"典当／胎借",总表!$S$2:$S$235,">0")),IF(COUNTIFS(总表!$T$2:$T$235,$F10,总表!$E$2:$E$235,$G10,总表!$C$2:$C$235,"找贴／凑断",总表!$S$2:$S$235,">0")=0,1E+99,_xlfn.MINIFS(总表!$S$2:$S$235,总表!$T$2:$T$235,$F10,总表!$E$2:$E$235,$G10,总表!$C$2:$C$235,"找贴／凑断",总表!$S$2:$S$235,">0")),IF(COUNTIFS(总表!$T$2:$T$235,$F10,总表!$E$2:$E$235,$G10,总表!$C$2:$C$235,"典＋找贴",总表!$S$2:$S$235,">0")=0,1E+99,_xlfn.MINIFS(总表!$S$2:$S$235,总表!$T$2:$T$235,$F10,总表!$E$2:$E$235,$G10,总表!$C$2:$C$235,"典＋找贴",总表!$S$2:$S$235,">0")))) -> 150 | K10: =IF(H10=0,"—",MAX(_xlfn.MAXIFS(总表!$S$2:$S$235,总表!$T$2:$T$235,$F10,总表!$E$2:$E$235,$G10,总表!$C$2:$C$235,"买卖（卖／卖断）",总表!$S$2:$S$235,">0"),_xlfn.MAXIFS(总表!$S$2:$S$235,总表!$T$2:$T$235,$F10,总表!$E$2:$E$235,$G10,总表!$C$2:$C$235,"典当／胎借",总表!$S$2:$S$235,">0"),_xlfn.MAXIFS(总表!$S$2:$S$235,总表!$T$2:$T$235,$F10,总表!$E$2:$E$235,$G10,总表!$C$2:$C$235,"找贴／凑断",总表!$S$2:$S$235,">0"),_xlfn.MAXIFS(总表!$S$2:$S$235,总表!$T$2:$T$235,$F10,总表!$E$2:$E$235,$G10,总表!$C$2:$C$235,"典＋找贴",总表!$S$2:$S$235,">0"))) -> 150
A11: 其他 | B11: =COUNTIF(总表!$C$2:$C$235,A11) -> 12 | C11: =IFERROR(B11/COUNTA(总表!$AI$2:$AI$235),0) -> 0.051282051 | F11: 银元／大洋 | G11: 4 咸同光宣（1851-1911） | H11: =SUMPRODUCT(COUNTIFS(总表!$T$2:$T$235,$F11,总表!$E$2:$E$235,$G11,总表!$C$2:$C$235,{"买卖（卖／卖断）","典当／胎借","找贴／凑断","典＋找贴"},总表!$S$2:$S$235,">0")) -> 7 | I11: =IFERROR(SUMPRODUCT(SUMIFS(总表!$S$2:$S$235,总表!$T$2:$T$235,$F11,总表!$E$2:$E$235,$G11,总表!$C$2:$C$235,{"买卖（卖／卖断）","典当／胎借","找贴／凑断","典＋找贴"},总表!$S$2:$S$235,">0"))/H11,"—") -> 15.178571 | J11: =IF(H11=0,"—",MIN(IF(COUNTIFS(总表!$T$2:$T$235,$F11,总表!$E$2:$E$235,$G11,总表!$C$2:$C$235,"买卖（卖／卖断）",总表!$S$2:$S$235,">0")=0,1E+99,_xlfn.MINIFS(总表!$S$2:$S$235,总表!$T$2:$T$235,$F11,总表!$E$2:$E$235,$G11,总表!$C$2:$C$235,"买卖（卖／卖断）",总表!$S$2:$S$235,">0")),IF(COUNTIFS(总表!$T$2:$T$235,$F11,总表!$E$2:$E$235,$G11,总表!$C$2:$C$235,"典当／胎借",总表!$S$2:$S$235,">0")=0,1E+99,_xlfn.MINIFS(总表!$S$2:$S$235,总表!$T$2:$T$235,$F11,总表!$E$2:$E$235,$G11,总表!$C$2:$C$235,"典当／胎借",总表!$S$2:$S$235,">0")),IF(COUNTIFS(总表!$T$2:$T$235,$F11,总表!$E$2:$E$235,$G11,总表!$C$2:$C$235,"找贴／凑断",总表!$S$2:$S$235,">0")=0,1E+99,_xlfn.MINIFS(总表!$S$2:$S$235,总表!$T$2:$T$235,$F11,总表!$E$2:$E$235,$G11,总表!$C$2:$C$235,"找贴／凑断",总表!$S$2:$S$235,">0")),IF(COUNTIFS(总表!$T$2:$T$235,$F11,总表!$E$2:$E$235,$G11,总表!$C$2:$C$235,"典＋找贴",总表!$S$2:$S$235,">0")=0,1E+99,_xlfn.MINIFS(总表!$S$2:$S$235,总表!$T$2:$T$235,$F11,总表!$E$2:$E$235,$G11,总表!$C$2:$C$235,"典＋找贴",总表!$S$2:$S$235,">0")))) -> 2.25 | K11: =IF(H11=0,"—",MAX(_xlfn.MAXIFS(总表!$S$2:$S$235,总表!$T$2:$T$235,$F11,总表!$E$2:$E$235,$G11,总表!$C$2:$C$235,"买卖（卖／卖断）",总表!$S$2:$S$235,">0"),_xlfn.MAXIFS(总表!$S$2:$S$235,总表!$T$2:$T$235,$F11,总表!$E$2:$E$235,$G11,总表!$C$2:$C$235,"典当／胎借",总表!$S$2:$S$235,">0"),_xlfn.MAXIFS(总表!$S$2:$S$235,总表!$T$2:$T$235,$F11,总表!$E$2:$E$235,$G11,总表!$C$2:$C$235,"找贴／凑断",总表!$S$2:$S$235,">0"),_xlfn.MAXIFS(总表!$S$2:$S$235,总表!$T$2:$T$235,$F11,总表!$E$2:$E$235,$G11,总表!$C$2:$C$235,"典＋找贴",总表!$S$2:$S$235,">0"))) -> 60
A12: 租佃／欠租 | B12: =COUNTIF(总表!$C$2:$C$235,A12) -> 5 | C12: =IFERROR(B12/COUNTA(总表!$AI$2:$AI$235),0) -> 0.021367521 | F12: 银元／大洋 | G12: 5 北洋（1912-1927） | H12: =SUMPRODUCT(COUNTIFS(总表!$T$2:$T$235,$F12,总表!$E$2:$E$235,$G12,总表!$C$2:$C$235,{"买卖（卖／卖断）","典当／胎借","找贴／凑断","典＋找贴"},总表!$S$2:$S$235,">0")) -> 10 | I12: =IFERROR(SUMPRODUCT(SUMIFS(总表!$S$2:$S$235,总表!$T$2:$T$235,$F12,总表!$E$2:$E$235,$G12,总表!$C$2:$C$235,{"买卖（卖／卖断）","典当／胎借","找贴／凑断","典＋找贴"},总表!$S$2:$S$235,">0"))/H12,"—") -> 226.4 | J12: =IF(H12=0,"—",MIN(IF(COUNTIFS(总表!$T$2:$T$235,$F12,总表!$E$2:$E$235,$G12,总表!$C$2:$C$235,"买卖（卖／卖断）",总表!$S$2:$S$235,">0")=0,1E+99,_xlfn.MINIFS(总表!$S$2:$S$235,总表!$T$2:$T$235,$F12,总表!$E$2:$E$235,$G12,总表!$C$2:$C$235,"买卖（卖／卖断）",总表!$S$2:$S$235,">0")),IF(COUNTIFS(总表!$T$2:$T$235,$F12,总表!$E$2:$E$235,$G12,总表!$C$2:$C$235,"典当／胎借",总表!$S$2:$S$235,">0")=0,1E+99,_xlfn.MINIFS(总表!$S$2:$S$235,总表!$T$2:$T$235,$F12,总表!$E$2:$E$235,$G12,总表!$C$2:$C$235,"典当／胎借",总表!$S$2:$S$235,">0")),IF(COUNTIFS(总表!$T$2:$T$235,$F12,总表!$E$2:$E$235,$G12,总表!$C$2:$C$235,"找贴／凑断",总表!$S$2:$S$235,">0")=0,1E+99,_xlfn.MINIFS(总表!$S$2:$S$235,总表!$T$2:$T$235,$F12,总表!$E$2:$E$235,$G12,总表!$C$2:$C$235,"找贴／凑断",总表!$S$2:$S$235,">0")),IF(COUNTIFS(总表!$T$2:$T$235,$F12,总表!$E$2:$E$235,$G12,总表!$C$2:$C$235,"典＋找贴",总表!$S$2:$S$235,">0")=0,1E+99,_xlfn.MINIFS(总表!$S$2:$S$235,总表!$T$2:$T$235,$F12,总表!$E$2:$E$235,$G12,总表!$C$2:$C$235,"典＋找贴",总表!$S$2:$S$235,">0")))) -> 28 | K12: =IF(H12=0,"—",MAX(_xlfn.MAXIFS(总表!$S$2:$S$235,总表!$T$2:$T$235,$F12,总表!$E$2:$E$235,$G12,总表!$C$2:$C$235,"买卖（卖／卖断）",总表!$S$2:$S$235,">0"),_xlfn.MAXIFS(总表!$S$2:$S$235,总表!$T$2:$T$235,$F12,总表!$E$2:$E$235,$G12,总表!$C$2:$C$235,"典当／胎借",总表!$S$2:$S$235,">0"),_xlfn.MAXIFS(总表!$S$2:$S$235,总表!$T$2:$T$235,$F12,总表!$E$2:$E$235,$G12,总表!$C$2:$C$235,"找贴／凑断",总表!$S$2:$S$235,">0"),_xlfn.MAXIFS(总表!$S$2:$S$235,总表!$T$2:$T$235,$F12,总表!$E$2:$E$235,$G12,总表!$C$2:$C$235,"典＋找贴",总表!$S$2:$S$235,">0"))) -> 721
A13: 分家书 | B13: =COUNTIF(总表!$C$2:$C$235,A13) -> 3 | C13: =IFERROR(B13/COUNTA(总表!$AI$2:$AI$235),0) -> 0.012820513 | F13: 银元／大洋 | G13: 6 南京国民政府（1928-1948） | H13: =SUMPRODUCT(COUNTIFS(总表!$T$2:$T$235,$F13,总表!$E$2:$E$235,$G13,总表!$C$2:$C$235,{"买卖（卖／卖断）","典当／胎借","找贴／凑断","典＋找贴"},总表!$S$2:$S$235,">0")) -> 11 | I13: =IFERROR(SUMPRODUCT(SUMIFS(总表!$S$2:$S$235,总表!$T$2:$T$235,$F13,总表!$E$2:$E$235,$G13,总表!$C$2:$C$235,{"买卖（卖／卖断）","典当／胎借","找贴／凑断","典＋找贴"},总表!$S$2:$S$235,">0"))/H13,"—") -> 130.36364 | J13: =IF(H13=0,"—",MIN(IF(COUNTIFS(总表!$T$2:$T$235,$F13,总表!$E$2:$E$235,$G13,总表!$C$2:$C$235,"买卖（卖／卖断）",总表!$S$2:$S$235,">0")=0,1E+99,_xlfn.MINIFS(总表!$S$2:$S$235,总表!$T$2:$T$235,$F13,总表!$E$2:$E$235,$G13,总表!$C$2:$C$235,"买卖（卖／卖断）",总表!$S$2:$S$235,">0")),IF(COUNTIFS(总表!$T$2:$T$235,$F13,总表!$E$2:$E$235,$G13,总表!$C$2:$C$235,"典当／胎借",总表!$S$2:$S$235,">0")=0,1E+99,_xlfn.MINIFS(总表!$S$2:$S$235,总表!$T$2:$T$235,$F13,总表!$E$2:$E$235,$G13,总表!$C$2:$C$235,"典当／胎借",总表!$S$2:$S$235,">0")),IF(COUNTIFS(总表!$T$2:$T$235,$F13,总表!$E$2:$E$235,$G13,总表!$C$2:$C$235,"找贴／凑断",总表!$S$2:$S$235,">0")=0,1E+99,_xlfn.MINIFS(总表!$S$2:$S$235,总表!$T$2:$T$235,$F13,总表!$E$2:$E$235,$G13,总表!$C$2:$C$235,"找贴／凑断",总表!$S$2:$S$235,">0")),IF(COUNTIFS(总表!$T$2:$T$235,$F13,总表!$E$2:$E$235,$G13,总表!$C$2:$C$235,"典＋找贴",总表!$S$2:$S$235,">0")=0,1E+99,_xlfn.MINIFS(总表!$S$2:$S$235,总表!$T$2:$T$235,$F13,总表!$E$2:$E$235,$G13,总表!$C$2:$C$235,"典＋找贴",总表!$S$2:$S$235,">0")))) -> 30 | K13: =IF(H13=0,"—",MAX(_xlfn.MAXIFS(总表!$S$2:$S$235,总表!$T$2:$T$235,$F13,总表!$E$2:$E$235,$G13,总表!$C$2:$C$235,"买卖（卖／卖断）",总表!$S$2:$S$235,">0"),_xlfn.MAXIFS(总表!$S$2:$S$235,总表!$T$2:$T$235,$F13,总表!$E$2:$E$235,$G13,总表!$C$2:$C$235,"典当／胎借",总表!$S$2:$S$235,">0"),_xlfn.MAXIFS(总表!$S$2:$S$235,总表!$T$2:$T$235,$F13,总表!$E$2:$E$235,$G13,总表!$C$2:$C$235,"找贴／凑断",总表!$S$2:$S$235,">0"),_xlfn.MAXIFS(总表!$S$2:$S$235,总表!$T$2:$T$235,$F13,总表!$E$2:$E$235,$G13,总表!$C$2:$C$235,"典＋找贴",总表!$S$2:$S$235,">0"))) -> 240
A14: 合同／约字 | B14: =COUNTIF(总表!$C$2:$C$235,A14) -> 3 | C14: =IFERROR(B14/COUNTA(总表!$AI$2:$AI$235),0) -> 0.012820513 | F14: 银元／大洋 | G14: 7 1949 以后 | H14: =SUMPRODUCT(COUNTIFS(总表!$T$2:$T$235,$F14,总表!$E$2:$E$235,$G14,总表!$C$2:$C$235,{"买卖（卖／卖断）","典当／胎借","找贴／凑断","典＋找贴"},总表!$S$2:$S$235,">0")) -> 1 | I14: =IFERROR(SUMPRODUCT(SUMIFS(总表!$S$2:$S$235,总表!$T$2:$T$235,$F14,总表!$E$2:$E$235,$G14,总表!$C$2:$C$235,{"买卖（卖／卖断）","典当／胎借","找贴／凑断","典＋找贴"},总表!$S$2:$S$235,">0"))/H14,"—") -> 30 | J14: =IF(H14=0,"—",MIN(IF(COUNTIFS(总表!$T$2:$T$235,$F14,总表!$E$2:$E$235,$G14,总表!$C$2:$C$235,"买卖（卖／卖断）",总表!$S$2:$S$235,">0")=0,1E+99,_xlfn.MINIFS(总表!$S$2:$S$235,总表!$T$2:$T$235,$F14,总表!$E$2:$E$235,$G14,总表!$C$2:$C$235,"买卖（卖／卖断）",总表!$S$2:$S$235,">0")),IF(COUNTIFS(总表!$T$2:$T$235,$F14,总表!$E$2:$E$235,$G14,总表!$C$2:$C$235,"典当／胎借",总表!$S$2:$S$235,">0")=0,1E+99,_xlfn.MINIFS(总表!$S$2:$S$235,总表!$T$2:$T$235,$F14,总表!$E$2:$E$235,$G14,总表!$C$2:$C$235,"典当／胎借",总表!$S$2:$S$235,">0")),IF(COUNTIFS(总表!$T$2:$T$235,$F14,总表!$E$2:$E$235,$G14,总表!$C$2:$C$235,"找贴／凑断",总表!$S$2:$S$235,">0")=0,1E+99,_xlfn.MINIFS(总表!$S$2:$S$235,总表!$T$2:$T$235,$F14,总表!$E$2:$E$235,$G14,总表!$C$2:$C$235,"找贴／凑断",总表!$S$2:$S$235,">0")),IF(COUNTIFS(总表!$T$2:$T$235,$F14,总表!$E$2:$E$235,$G14,总表!$C$2:$C$235,"典＋找贴",总表!$S$2:$S$235,">0")=0,1E+99,_xlfn.MINIFS(总表!$S$2:$S$235,总表!$T$2:$T$235,$F14,总表!$E$2:$E$235,$G14,总表!$C$2:$C$235,"典＋找贴",总表!$S$2:$S$235,">0")))) -> 30 | K14: =IF(H14=0,"—",MAX(_xlfn.MAXIFS(总表!$S$2:$S$235,总表!$T$2:$T$235,$F14,总表!$E$2:$E$235,$G14,总表!$C$2:$C$235,"买卖（卖／卖断）",总表!$S$2:$S$235,">0"),_xlfn.MAXIFS(总表!$S$2:$S$235,总表!$T$2:$T$235,$F14,总表!$E$2:$E$235,$G14,总表!$C$2:$C$235,"典当／胎借",总表!$S$2:$S$235,">0"),_xlfn.MAXIFS(总表!$S$2:$S$235,总表!$T$2:$T$235,$F14,总表!$E$2:$E$235,$G14,总表!$C$2:$C$235,"找贴／凑断",总表!$S$2:$S$235,">0"),_xlfn.MAXIFS(总表!$S$2:$S$235,总表!$T$2:$T$235,$F14,总表!$E$2:$E$235,$G14,总表!$C$2:$C$235,"典＋找贴",总表!$S$2:$S$235,">0"))) -> 30
A15: 典＋找贴 | B15: =COUNTIF(总表!$C$2:$C$235,A15) -> 2 | C15: =IFERROR(B15/COUNTA(总表!$AI$2:$AI$235),0) -> 0.0085470085 | F15: 铜钱 | G15: 3 嘉道（1796-1850） | H15: =SUMPRODUCT(COUNTIFS(总表!$T$2:$T$235,$F15,总表!$E$2:$E$235,$G15,总表!$C$2:$C$235,{"买卖（卖／卖断）","典当／胎借","找贴／凑断","典＋找贴"},总表!$S$2:$S$235,">0")) -> 1 | I15: =IFERROR(SUMPRODUCT(SUMIFS(总表!$S$2:$S$235,总表!$T$2:$T$235,$F15,总表!$E$2:$E$235,$G15,总表!$C$2:$C$235,{"买卖（卖／卖断）","典当／胎借","找贴／凑断","典＋找贴"},总表!$S$2:$S$235,">0"))/H15,"—") -> 11500 | J15: =IF(H15=0,"—",MIN(IF(COUNTIFS(总表!$T$2:$T$235,$F15,总表!$E$2:$E$235,$G15,总表!$C$2:$C$235,"买卖（卖／卖断）",总表!$S$2:$S$235,">0")=0,1E+99,_xlfn.MINIFS(总表!$S$2:$S$235,总表!$T$2:$T$235,$F15,总表!$E$2:$E$235,$G15,总表!$C$2:$C$235,"买卖（卖／卖断）",总表!$S$2:$S$235,">0")),IF(COUNTIFS(总表!$T$2:$T$235,$F15,总表!$E$2:$E$235,$G15,总表!$C$2:$C$235,"典当／胎借",总表!$S$2:$S$235,">0")=0,1E+99,_xlfn.MINIFS(总表!$S$2:$S$235,总表!$T$2:$T$235,$F15,总表!$E$2:$E$235,$G15,总表!$C$2:$C$235,"典当／胎借",总表!$S$2:$S$235,">0")),IF(COUNTIFS(总表!$T$2:$T$235,$F15,总表!$E$2:$E$235,$G15,总表!$C$2:$C$235,"找贴／凑断",总表!$S$2:$S$235,">0")=0,1E+99,_xlfn.MINIFS(总表!$S$2:$S$235,总表!$T$2:$T$235,$F15,总表!$E$2:$E$235,$G15,总表!$C$2:$C$235,"找贴／凑断",总表!$S$2:$S$235,">0")),IF(COUNTIFS(总表!$T$2:$T$235,$F15,总表!$E$2:$E$235,$G15,总表!$C$2:$C$235,"典＋找贴",总表!$S$2:$S$235,">0")=0,1E+99,_xlfn.MINIFS(总表!$S$2:$S$235,总表!$T$2:$T$235,$F15,总表!$E$2:$E$235,$G15,总表!$C$2:$C$235,"典＋找贴",总表!$S$2:$S$235,">0")))) -> 11500 | K15: =IF(H15=0,"—",MAX(_xlfn.MAXIFS(总表!$S$2:$S$235,总表!$T$2:$T$235,$F15,总表!$E$2:$E$235,$G15,总表!$C$2:$C$235,"买卖（卖／卖断）",总表!$S$2:$S$235,">0"),_xlfn.MAXIFS(总表!$S$2:$S$235,总表!$T$2:$T$235,$F15,总表!$E$2:$E$235,$G15,总表!$C$2:$C$235,"典当／胎借",总表!$S$2:$S$235,">0"),_xlfn.MAXIFS(总表!$S$2:$S$235,总表!$T$2:$T$235,$F15,总表!$E$2:$E$235,$G15,总表!$C$2:$C$235,"找贴／凑断",总表!$S$2:$S$235,">0"),_xlfn.MAXIFS(总表!$S$2:$S$235,总表!$T$2:$T$235,$F15,总表!$E$2:$E$235,$G15,总表!$C$2:$C$235,"典＋找贴",总表!$S$2:$S$235,">0"))) -> 11500
A16: 合计 | B16: =SUM(B5:B15) -> 234 | C16: =SUM(C5:C15) -> 1 | F16: 铜钱 | G16: 4 咸同光宣（1851-1911） | H16: =SUMPRODUCT(COUNTIFS(总表!$T$2:$T$235,$F16,总表!$E$2:$E$235,$G16,总表!$C$2:$C$235,{"买卖（卖／卖断）","典当／胎借","找贴／凑断","典＋找贴"},总表!$S$2:$S$235,">0")) -> 11 | I16: =IFERROR(SUMPRODUCT(SUMIFS(总表!$S$2:$S$235,总表!$T$2:$T$235,$F16,总表!$E$2:$E$235,$G16,总表!$C$2:$C$235,{"买卖（卖／卖断）","典当／胎借","找贴／凑断","典＋找贴"},总表!$S$2:$S$235,">0"))/H16,"—") -> 73418.182 | J16: =IF(H16=0,"—",MIN(IF(COUNTIFS(总表!$T$2:$T$235,$F16,总表!$E$2:$E$235,$G16,总表!$C$2:$C$235,"买卖（卖／卖断）",总表!$S$2:$S$235,">0")=0,1E+99,_xlfn.MINIFS(总表!$S$2:$S$235,总表!$T$2:$T$235,$F16,总表!$E$2:$E$235,$G16,总表!$C$2:$C$235,"买卖（卖／卖断）",总表!$S$2:$S$235,">0")),IF(COUNTIFS(总表!$T$2:$T$235,$F16,总表!$E$2:$E$235,$G16,总表!$C$2:$C$235,"典当／胎借",总表!$S$2:$S$235,">0")=0,1E+99,_xlfn.MINIFS(总表!$S$2:$S$235,总表!$T$2:$T$235,$F16,总表!$E$2:$E$235,$G16,总表!$C$2:$C$235,"典当／胎借",总表!$S$2:$S$235,">0")),IF(COUNTIFS(总表!$T$2:$T$235,$F16,总表!$E$2:$E$235,$G16,总表!$C$2:$C$235,"找贴／凑断",总表!$S$2:$S$235,">0")=0,1E+99,_xlfn.MINIFS(总表!$S$2:$S$235,总表!$T$2:$T$235,$F16,总表!$E$2:$E$235,$G16,总表!$C$2:$C$235,"找贴／凑断",总表!$S$2:$S$235,">0")),IF(COUNTIFS(总表!$T$2:$T$235,$F16,总表!$E$2:$E$235,$G16,总表!$C$2:$C$235,"典＋找贴",总表!$S$2:$S$235,">0")=0,1E+99,_xlfn.MINIFS(总表!$S$2:$S$235,总表!$T$2:$T$235,$F16,总表!$E$2:$E$235,$G16,总表!$C$2:$C$235,"典＋找贴",总表!$S$2:$S$235,">0")))) -> 2000 | K16: =IF(H16=0,"—",MAX(_xlfn.MAXIFS(总表!$S$2:$S$235,总表!$T$2:$T$235,$F16,总表!$E$2:$E$235,$G16,总表!$C$2:$C$235,"买卖（卖／卖断）",总表!$S$2:$S$235,">0"),_xlfn.MAXIFS(总表!$S$2:$S$235,总表!$T$2:$T$235,$F16,总表!$E$2:$E$235,$G16,总表!$C$2:$C$235,"典当／胎借",总表!$S$2:$S$235,">0"),_xlfn.MAXIFS(总表!$S$2:$S$235,总表!$T$2:$T$235,$F16,总表!$E$2:$E$235,$G16,总表!$C$2:$C$235,"找贴／凑断",总表!$S$2:$S$235,">0"),_xlfn.MAXIFS(总表!$S$2:$S$235,总表!$T$2:$T$235,$F16,总表!$E$2:$E$235,$G16,总表!$C$2:$C$235,"典＋找贴",总表!$S$2:$S$235,">0"))) -> 148000
F17: 铜钱 | G17: 5 北洋（1912-1927） | H17: =SUMPRODUCT(COUNTIFS(总表!$T$2:$T$235,$F17,总表!$E$2:$E$235,$G17,总表!$C$2:$C$235,{"买卖（卖／卖断）","典当／胎借","找贴／凑断","典＋找贴"},总表!$S$2:$S$235,">0")) -> 1 | I17: =IFERROR(SUMPRODUCT(SUMIFS(总表!$S$2:$S$235,总表!$T$2:$T$235,$F17,总表!$E$2:$E$235,$G17,总表!$C$2:$C$235,{"买卖（卖／卖断）","典当／胎借","找贴／凑断","典＋找贴"},总表!$S$2:$S$235,">0"))/H17,"—") -> 64500 | J17: =IF(H17=0,"—",MIN(IF(COUNTIFS(总表!$T$2:$T$235,$F17,总表!$E$2:$E$235,$G17,总表!$C$2:$C$235,"买卖（卖／卖断）",总表!$S$2:$S$235,">0")=0,1E+99,_xlfn.MINIFS(总表!$S$2:$S$235,总表!$T$2:$T$235,$F17,总表!$E$2:$E$235,$G17,总表!$C$2:$C$235,"买卖（卖／卖断）",总表!$S$2:$S$235,">0")),IF(COUNTIFS(总表!$T$2:$T$235,$F17,总表!$E$2:$E$235,$G17,总表!$C$2:$C$235,"典当／胎借",总表!$S$2:$S$235,">0")=0,1E+99,_xlfn.MINIFS(总表!$S$2:$S$235,总表!$T$2:$T$235,$F17,总表!$E$2:$E$235,$G17,总表!$C$2:$C$235,"典当／胎借",总表!$S$2:$S$235,">0")),IF(COUNTIFS(总表!$T$2:$T$235,$F17,总表!$E$2:$E$235,$G17,总表!$C$2:$C$235,"找贴／凑断",总表!$S$2:$S$235,">0")=0,1E+99,_xlfn.MINIFS(总表!$S$2:$S$235,总表!$T$2:$T$235,$F17,总表!$E$2:$E$235,$G17,总表!$C$2:$C$235,"找贴／凑断",总表!$S$2:$S$235,">0")),IF(COUNTIFS(总表!$T$2:$T$235,$F17,总表!$E$2:$E$235,$G17,总表!$C$2:$C$235,"典＋找贴",总表!$S$2:$S$235,">0")=0,1E+99,_xlfn.MINIFS(总表!$S$2:$S$235,总表!$T$2:$T$235,$F17,总表!$E$2:$E$235,$G17,总表!$C$2:$C$235,"典＋找贴",总表!$S$2:$S$235,">0")))) -> 64500 | K17: =IF(H17=0,"—",MAX(_xlfn.MAXIFS(总表!$S$2:$S$235,总表!$T$2:$T$235,$F17,总表!$E$2:$E$235,$G17,总表!$C$2:$C$235,"买卖（卖／卖断）",总表!$S$2:$S$235,">0"),_xlfn.MAXIFS(总表!$S$2:$S$235,总表!$T$2:$T$235,$F17,总表!$E$2:$E$235,$G17,总表!$C$2:$C$235,"典当／胎借",总表!$S$2:$S$235,">0"),_xlfn.MAXIFS(总表!$S$2:$S$235,总表!$T$2:$T$235,$F17,总表!$E$2:$E$235,$G17,总表!$C$2:$C$235,"找贴／凑断",总表!$S$2:$S$235,">0"),_xlfn.MAXIFS(总表!$S$2:$S$235,总表!$T$2:$T$235,$F17,总表!$E$2:$E$235,$G17,总表!$C$2:$C$235,"典＋找贴",总表!$S$2:$S$235,">0"))) -> 64500
A18: 二、时期 | F18: 铜钱 | G18: 6 南京国民政府（1928-1948） | H18: =SUMPRODUCT(COUNTIFS(总表!$T$2:$T$235,$F18,总表!$E$2:$E$235,$G18,总表!$C$2:$C$235,{"买卖（卖／卖断）","典当／胎借","找贴／凑断","典＋找贴"},总表!$S$2:$S$235,">0")) -> 3 | I18: =IFERROR(SUMPRODUCT(SUMIFS(总表!$S$2:$S$235,总表!$T$2:$T$235,$F18,总表!$E$2:$E$235,$G18,总表!$C$2:$C$235,{"买卖（卖／卖断）","典当／胎借","找贴／凑断","典＋找贴"},总表!$S$2:$S$235,">0"))/H18,"—") -> 34366.667 | J18: =IF(H18=0,"—",MIN(IF(COUNTIFS(总表!$T$2:$T$235,$F18,总表!$E$2:$E$235,$G18,总表!$C$2:$C$235,"买卖（卖／卖断）",总表!$S$2:$S$235,">0")=0,1E+99,_xlfn.MINIFS(总表!$S$2:$S$235,总表!$T$2:$T$235,$F18,总表!$E$2:$E$235,$G18,总表!$C$2:$C$235,"买卖（卖／卖断）",总表!$S$2:$S$235,">0")),IF(COUNTIFS(总表!$T$2:$T$235,$F18,总表!$E$2:$E$235,$G18,总表!$C$2:$C$235,"典当／胎借",总表!$S$2:$S$235,">0")=0,1E+99,_xlfn.MINIFS(总表!$S$2:$S$235,总表!$T$2:$T$235,$F18,总表!$E$2:$E$235,$G18,总表!$C$2:$C$235,"典当／胎借",总表!$S$2:$S$235,">0")),IF(COUNTIFS(总表!$T$2:$T$235,$F18,总表!$E$2:$E$235,$G18,总表!$C$2:$C$235,"找贴／凑断",总表!$S$2:$S$235,">0")=0,1E+99,_xlfn.MINIFS(总表!$S$2:$S$235,总表!$T$2:$T$235,$F18,总表!$E$2:$E$235,$G18,总表!$C$2:$C$235,"找贴／凑断",总表!$S$2:$S$235,">0")),IF(COUNTIFS(总表!$T$2:$T$235,$F18,总表!$E$2:$E$235,$G18,总表!$C$2:$C$235,"典＋找贴",总表!$S$2:$S$235,">0")=0,1E+99,_xlfn.MINIFS(总表!$S$2:$S$235,总表!$T$2:$T$235,$F18,总表!$E$2:$E$235,$G18,总表!$C$2:$C$235,"典＋找贴",总表!$S$2:$S$235,">0")))) -> 11500 | K18: =IF(H18=0,"—",MAX(_xlfn.MAXIFS(总表!$S$2:$S$235,总表!$T$2:$T$235,$F18,总表!$E$2:$E$235,$G18,总表!$C$2:$C$235,"买卖（卖／卖断）",总表!$S$2:$S$235,">0"),_xlfn.MAXIFS(总表!$S$2:$S$235,总表!$T$2:$T$235,$F18,总表!$E$2:$E$235,$G18,总表!$C$2:$C$235,"典当／胎借",总表!$S$2:$S$235,">0"),_xlfn.MAXIFS(总表!$S$2:$S$235,总表!$T$2:$T$235,$F18,总表!$E$2:$E$235,$G18,总表!$C$2:$C$235,"找贴／凑断",总表!$S$2:$S$235,">0"),_xlfn.MAXIFS(总表!$S$2:$S$235,总表!$T$2:$T$235,$F18,总表!$E$2:$E$235,$G18,总表!$C$2:$C$235,"典＋找贴",总表!$S$2:$S$235,">0"))) -> 68600
A19: 类别 | B19: 件数 | C19: 占比 | F19: 番银 | G19: 3 嘉道（1796-1850） | H19: =SUMPRODUCT(COUNTIFS(总表!$T$2:$T$235,$F19,总表!$E$2:$E$235,$G19,总表!$C$2:$C$235,{"买卖（卖／卖断）","典当／胎借","找贴／凑断","典＋找贴"},总表!$S$2:$S$235,">0")) -> 1 | I19: =IFERROR(SUMPRODUCT(SUMIFS(总表!$S$2:$S$235,总表!$T$2:$T$235,$F19,总表!$E$2:$E$235,$G19,总表!$C$2:$C$235,{"买卖（卖／卖断）","典当／胎借","找贴／凑断","典＋找贴"},总表!$S$2:$S$235,">0"))/H19,"—") -> 6 | J19: =IF(H19=0,"—",MIN(IF(COUNTIFS(总表!$T$2:$T$235,$F19,总表!$E$2:$E$235,$G19,总表!$C$2:$C$235,"买卖（卖／卖断）",总表!$S$2:$S$235,">0")=0,1E+99,_xlfn.MINIFS(总表!$S$2:$S$235,总表!$T$2:$T$235,$F19,总表!$E$2:$E$235,$G19,总表!$C$2:$C$235,"买卖（卖／卖断）",总表!$S$2:$S$235,">0")),IF(COUNTIFS(总表!$T$2:$T$235,$F19,总表!$E$2:$E$235,$G19,总表!$C$2:$C$235,"典当／胎借",总表!$S$2:$S$235,">0")=0,1E+99,_xlfn.MINIFS(总表!$S$2:$S$235,总表!$T$2:$T$235,$F19,总表!$E$2:$E$235,$G19,总表!$C$2:$C$235,"典当／胎借",总表!$S$2:$S$235,">0")),IF(COUNTIFS(总表!$T$2:$T$235,$F19,总表!$E$2:$E$235,$G19,总表!$C$2:$C$235,"找贴／凑断",总表!$S$2:$S$235,">0")=0,1E+99,_xlfn.MINIFS(总表!$S$2:$S$235,总表!$T$2:$T$235,$F19,总表!$E$2:$E$235,$G19,总表!$C$2:$C$235,"找贴／凑断",总表!$S$2:$S$235,">0")),IF(COUNTIFS(总表!$T$2:$T$235,$F19,总表!$E$2:$E$235,$G19,总表!$C$2:$C$235,"典＋找贴",总表!$S$2:$S$235,">0")=0,1E+99,_xlfn.MINIFS(总表!$S$2:$S$235,总表!$T$2:$T$235,$F19,总表!$E$2:$E$235,$G19,总表!$C$2:$C$235,"典＋找贴",总表!$S$2:$S$235,">0")))) -> 6 | K19: =IF(H19=0,"—",MAX(_xlfn.MAXIFS(总表!$S$2:$S$235,总表!$T$2:$T$235,$F19,总表!$E$2:$E$235,$G19,总表!$C$2:$C$235,"买卖（卖／卖断）",总表!$S$2:$S$235,">0"),_xlfn.MAXIFS(总表!$S$2:$S$235,总表!$T$2:$T$235,$F19,总表!$E$2:$E$235,$G19,总表!$C$2:$C$235,"典当／胎借",总表!$S$2:$S$235,">0"),_xlfn.MAXIFS(总表!$S$2:$S$235,总表!$T$2:$T$235,$F19,总表!$E$2:$E$235,$G19,总表!$C$2:$C$235,"找贴／凑断",总表!$S$2:$S$235,">0"),_xlfn.MAXIFS(总表!$S$2:$S$235,总表!$T$2:$T$235,$F19,总表!$E$2:$E$235,$G19,总表!$C$2:$C$235,"典＋找贴",总表!$S$2:$S$235,">0"))) -> 6
A20: 1 明（-1643） | B20: =COUNTIF(总表!$E$2:$E$235,A20) -> 1 | C20: =IFERROR(B20/COUNTA(总表!$AI$2:$AI$235),0) -> 0.0042735043 | F20: 番银 | G20: 4 咸同光宣（1851-1911） | H20: =SUMPRODUCT(COUNTIFS(总表!$T$2:$T$235,$F20,总表!$E$2:$E$235,$G20,总表!$C$2:$C$235,{"买卖（卖／卖断）","典当／胎借","找贴／凑断","典＋找贴"},总表!$S$2:$S$235,">0")) -> 1 | I20: =IFERROR(SUMPRODUCT(SUMIFS(总表!$S$2:$S$235,总表!$T$2:$T$235,$F20,总表!$E$2:$E$235,$G20,总表!$C$2:$C$235,{"买卖（卖／卖断）","典当／胎借","找贴／凑断","典＋找贴"},总表!$S$2:$S$235,">0"))/H20,"—") -> 70 | J20: =IF(H20=0,"—",MIN(IF(COUNTIFS(总表!$T$2:$T$235,$F20,总表!$E$2:$E$235,$G20,总表!$C$2:$C$235,"买卖（卖／卖断）",总表!$S$2:$S$235,">0")=0,1E+99,_xlfn.MINIFS(总表!$S$2:$S$235,总表!$T$2:$T$235,$F20,总表!$E$2:$E$235,$G20,总表!$C$2:$C$235,"买卖（卖／卖断）",总表!$S$2:$S$235,">0")),IF(COUNTIFS(总表!$T$2:$T$235,$F20,总表!$E$2:$E$235,$G20,总表!$C$2:$C$235,"典当／胎借",总表!$S$2:$S$235,">0")=0,1E+99,_xlfn.MINIFS(总表!$S$2:$S$235,总表!$T$2:$T$235,$F20,总表!$E$2:$E$235,$G20,总表!$C$2:$C$235,"典当／胎借",总表!$S$2:$S$235,">0")),IF(COUNTIFS(总表!$T$2:$T$235,$F20,总表!$E$2:$E$235,$G20,总表!$C$2:$C$235,"找贴／凑断",总表!$S$2:$S$235,">0")=0,1E+99,_xlfn.MINIFS(总表!$S$2:$S$235,总表!$T$2:$T$235,$F20,总表!$E$2:$E$235,$G20,总表!$C$2:$C$235,"找贴／凑断",总表!$S$2:$S$235,">0")),IF(COUNTIFS(总表!$T$2:$T$235,$F20,总表!$E$2:$E$235,$G20,总表!$C$2:$C$235,"典＋找贴",总表!$S$2:$S$235,">0")=0,1E+99,_xlfn.MINIFS(总表!$S$2:$S$235,总表!$T$2:$T$235,$F20,总表!$E$2:$E$235,$G20,总表!$C$2:$C$235,"典＋找贴",总表!$S$2:$S$235,">0")))) -> 70 | K20: =IF(H20=0,"—",MAX(_xlfn.MAXIFS(总表!$S$2:$S$235,总表!$T$2:$T$235,$F20,总表!$E$2:$E$235,$G20,总表!$C$2:$C$235,"买卖（卖／卖断）",总表!$S$2:$S$235,">0"),_xlfn.MAXIFS(总表!$S$2:$S$235,总表!$T$2:$T$235,$F20,总表!$E$2:$E$235,$G20,总表!$C$2:$C$235,"典当／胎借",总表!$S$2:$S$235,">0"),_xlfn.MAXIFS(总表!$S$2:$S$235,总表!$T$2:$T$235,$F20,总表!$E$2:$E$235,$G20,总表!$C$2:$C$235,"找贴／凑断",总表!$S$2:$S$235,">0"),_xlfn.MAXIFS(总表!$S$2:$S$235,总表!$T$2:$T$235,$F20,总表!$E$2:$E$235,$G20,总表!$C$2:$C$235,"典＋找贴",总表!$S$2:$S$235,">0"))) -> 70
